<?xml version="1.0" encoding="utf-8"?>
<!-- This URDF was automatically created by SolidWorks to URDF Exporter! Originally created by Stephen Brawner (brawner@gmail.com) 
     Commit Version: 1.4.4-24-g24328f6  Build Version: 1.5.7084.36479
     For more information, please see http://wiki.ros.org/sw_urdf_exporter -->
<robot
  name="bot6">
  <link
    name="base_link">
    <inertial>
      <origin
        xyz="-0.0053902 0.054165 -2.3712E-16"
        rpy="0 0 0" />
      <mass
        value="14.204" />
      <inertia
        ixx="0.27975"
        ixy="0.0073374"
        ixz="-1.9957E-16"
        iyy="0.50704"
        iyz="-4.0267E-17"
        izz="0.31459" />
    </inertial>
    <visual>
      <origin
        xyz="0 0 0"
        rpy="0 0 0" />
      <geometry>
        <mesh
          filename="package://bot6/meshes/base_link.STL" />
      </geometry>
      <material
        name="">
        <color
          rgba="0.79216 0.81961 0.93333 1" />
      </material>
    </visual>
    <collision>
      <origin
        xyz="0 0 0"
        rpy="0 0 0" />
      <geometry>
        <mesh
          filename="package://bot6/meshes/base_link.STL" />
      </geometry>
    </collision>
  </link>
  <link
    name="FRW">
    <inertial>
      <origin
        xyz="0 -7.5392E-05 -0.089381"
        rpy="0 0 0" />
      <mass
        value="0.8334" />
      <inertia
        ixx="0.0021574"
        ixy="4.3368E-19"
        ixz="1.7597E-19"
        iyy="0.0021606"
        iyz="-8.5571E-07"
        izz="0.0039286" />
    </inertial>
    <visual>
      <origin
        xyz="0 0 0"
        rpy="0 0 0" />
      <geometry>
        <mesh
          filename="package://bot6/meshes/FRW.STL" />
      </geometry>
      <material
        name="">
        <color
          rgba="0.79216 0.81961 0.93333 1" />
      </material>
    </visual>
    <collision>
      <origin
        xyz="0 0 0"
        rpy="0 0 0" />
      <geometry>
        <mesh
          filename="package://bot6/meshes/FRW.STL" />
      </geometry>
    </collision>
  </link>
  <joint
    name="FRWJ"
    type="continuous">
    <origin
      xyz="0.125 -0.13 -0.025"
      rpy="1.5708 0.39309 -3.1416" />
    <parent
      link="base_link" />
    <child
      link="FRW" />
    <axis
      xyz="0 0 1" />
    <safety_controller
      k_velocity="0" />
  </joint>
  <link
    name="RRW">
    <inertial>
      <origin
        xyz="-2.77555756156289E-17 -7.53920386007342E-05 -0.089381031363088"
        rpy="0 0 0" />
      <mass
        value="0.8334016991443" />
      <inertia
        ixx="0.00215743548655978"
        ixy="6.50521303491303E-19"
        ixz="4.67985703358001E-20"
        iyy="0.00216058181623486"
        iyz="-8.55705036383985E-07"
        izz="0.0039286091523943" />
    </inertial>
    <visual>
      <origin
        xyz="0 0 0"
        rpy="0 0 0" />
      <geometry>
        <mesh
          filename="package://bot6/meshes/RRW.STL" />
      </geometry>
      <material
        name="">
        <color
          rgba="0.792156862745098 0.819607843137255 0.933333333333333 1" />
      </material>
    </visual>
    <collision>
      <origin
        xyz="0 0 0"
        rpy="0 0 0" />
      <geometry>
        <mesh
          filename="package://bot6/meshes/RRW.STL" />
      </geometry>
    </collision>
  </link>
  <joint
    name="RRWJ"
    type="continuous">
    <origin
      xyz="-0.125 -0.13 -0.025"
      rpy="1.5708 0.39309 -3.1416" />
    <parent
      link="base_link" />
    <child
      link="RRW" />
    <axis
      xyz="0 0 1" />
    <safety_controller
      k_velocity="0" />
  </joint>
  <link
    name="FLW">
    <inertial>
      <origin
        xyz="0 -7.53920386007238E-05 -0.0893810313630881"
        rpy="0 0 0" />
      <mass
        value="0.8334016991443" />
      <inertia
        ixx="0.00215743548655978"
        ixy="-8.79635490065067E-21"
        ixz="2.78368928810459E-19"
        iyy="0.00216058181623486"
        iyz="-8.5570503638385E-07"
        izz="0.0039286091523943" />
    </inertial>
    <visual>
      <origin
        xyz="0 0 0"
        rpy="0 0 0" />
      <geometry>
        <mesh
          filename="package://bot6/meshes/FLW.STL" />
      </geometry>
      <material
        name="">
        <color
          rgba="0.792156862745098 0.819607843137255 0.933333333333333 1" />
      </material>
    </visual>
    <collision>
      <origin
        xyz="0 0 0"
        rpy="0 0 0" />
      <geometry>
        <mesh
          filename="package://bot6/meshes/FLW.STL" />
      </geometry>
    </collision>
  </link>
  <joint
    name="FLWJ"
    type="continuous">
    <origin
      xyz="0.125 0.13 -0.025"
      rpy="1.5708 0 0" />
    <parent
      link="base_link" />
    <child
      link="FLW" />
    <axis
      xyz="0 0 1" />
    <safety_controller
      k_velocity="0" />
  </joint>
  <link
    name="RLW">
    <inertial>
      <origin
        xyz="-1.3878E-17 -7.5392E-05 -0.089381"
        rpy="0 0 0" />
      <mass
        value="0.8334" />
      <inertia
        ixx="0.0021574"
        ixy="-8.7964E-21"
        ixz="2.7837E-19"
        iyy="0.0021606"
        iyz="-8.5571E-07"
        izz="0.0039286" />
    </inertial>
    <visual>
      <origin
        xyz="0 0 0"
        rpy="0 0 0" />
      <geometry>
        <mesh
          filename="package://bot6/meshes/RLW.STL" />
      </geometry>
      <material
        name="">
        <color
          rgba="0.79216 0.81961 0.93333 1" />
      </material>
    </visual>
    <collision>
      <origin
        xyz="0 0 0"
        rpy="0 0 0" />
      <geometry>
        <mesh
          filename="package://bot6/meshes/RLW.STL" />
      </geometry>
    </collision>
  </link>
  <joint
    name="RLWJ"
    type="continuous">
    <origin
      xyz="-0.125 0.13 -0.025"
      rpy="1.5708 0 0" />
    <parent
      link="base_link" />
    <child
      link="RLW" />
    <axis
      xyz="0 0 1" />
    <safety_controller
      k_velocity="0" />
  </joint>
  <link
    name="CL">
    <inertial>
      <origin
        xyz="0.015 0 -6.93889390390723E-18"
        rpy="0 0 0" />
      <mass
        value="0.075" />
      <inertia
        ixx="3.125E-05"
        ixy="4.76321900401482E-37"
        ixz="4.23516473627154E-22"
        iyy="2.125E-05"
        iyz="-1.92107072437275E-21"
        izz="2.125E-05" />
    </inertial>
    <visual>
      <origin
        xyz="0 0 0"
        rpy="0 0 0" />
      <geometry>
        <mesh
          filename="package://bot6/meshes/CL.STL" />
      </geometry>
      <material
        name="">
        <color
          rgba="0.792156862745098 0.819607843137255 0.933333333333333 1" />
      </material>
    </visual>
    <collision>
      <origin
        xyz="0 0 0"
        rpy="0 0 0" />
      <geometry>
        <mesh
          filename="package://bot6/meshes/CL.STL" />
      </geometry>
    </collision>
  </link>
  <joint
    name="CLJ"
    type="fixed">
    <origin
      xyz="0.05 0.23 0.125"
      rpy="-1.5708 0 -1.5708" />
    <parent
      link="base_link" />
    <child
      link="CL" />
    <axis
      xyz="0 0 0" />
    <safety_controller
      k_velocity="0" />
  </joint>
  <link
    name="CR">
    <inertial>
      <origin
        xyz="0.015 0 -6.93889390390723E-18"
        rpy="0 0 0" />
      <mass
        value="0.075" />
      <inertia
        ixx="3.125E-05"
        ixy="-1.62630325872826E-22"
        ixz="4.23516473627154E-22"
        iyy="2.125E-05"
        iyz="-1.30556011603463E-21"
        izz="2.125E-05" />
    </inertial>
    <visual>
      <origin
        xyz="0 0 0"
        rpy="0 0 0" />
      <geometry>
        <mesh
          filename="package://bot6/meshes/CR.STL" />
      </geometry>
      <material
        name="">
        <color
          rgba="0.792156862745098 0.819607843137255 0.933333333333333 1" />
      </material>
    </visual>
    <collision>
      <origin
        xyz="0 0 0"
        rpy="0 0 0" />
      <geometry>
        <mesh
          filename="package://bot6/meshes/CR.STL" />
      </geometry>
    </collision>
  </link>
  <joint
    name="CRJ"
    type="fixed">
    <origin
      xyz="0.05 -0.23 0.125"
      rpy="1.5708 0 1.5708" />
    <parent
      link="base_link" />
    <child
      link="CR" />
    <axis
      xyz="0 0 0" />
    <safety_controller
      k_velocity="0" />
  </joint>
  <link
    name="FC">
    <inertial>
      <origin
        xyz="0.015 0 -3.18704616733903E-17"
        rpy="0 0 0" />
      <mass
        value="0.075" />
      <inertia
        ixx="3.125E-05"
        ixy="3.52930394689292E-22"
        ixz="-3.52930394689292E-22"
        iyy="2.125E-05"
        iyz="-1.53821183221381E-21"
        izz="2.125E-05" />
    </inertial>
    <visual>
      <origin
        xyz="0 0 0"
        rpy="0 0 0" />
      <geometry>
        <mesh
          filename="package://bot6/meshes/FC.STL" />
      </geometry>
      <material
        name="">
        <color
          rgba="0.792156862745098 0.819607843137255 0.933333333333333 1" />
      </material>
    </visual>
    <collision>
      <origin
        xyz="0 0 0"
        rpy="0 0 0" />
      <geometry>
        <mesh
          filename="package://bot6/meshes/FC.STL" />
      </geometry>
    </collision>
  </link>
  <joint
    name="FCJ"
    type="fixed">
    <origin
      xyz="0.225 0 0.04"
      rpy="1.5708 0 0" />
    <parent
      link="base_link" />
    <child
      link="FC" />
    <axis
      xyz="0 0 0" />
    <safety_controller
      k_velocity="0" />
  </joint>
  <link
    name="EX1">
    <inertial>
      <origin
        xyz="0.161155451186496 0 -1.9751706802989E-17"
        rpy="0 0 0" />
      <mass
        value="0.14636282401554" />
      <inertia
        ixx="1.12799200839636E-05"
        ixy="1.56538644821314E-21"
        ixz="-1.3451593290669E-20"
        iyy="0.00339929403847134"
        iyz="-3.71025841885802E-22"
        izz="0.0033988227995733" />
    </inertial>
    <visual>
      <origin
        xyz="0 0 0"
        rpy="0 0 0" />
      <geometry>
        <mesh
          filename="package://bot6/meshes/EX1.STL" />
      </geometry>
      <material
        name="">
        <color
          rgba="0.792156862745098 0.819607843137255 0.933333333333333 1" />
      </material>
    </visual>
    <collision>
      <origin
        xyz="0 0 0"
        rpy="0 0 0" />
      <geometry>
        <mesh
          filename="package://bot6/meshes/EX1.STL" />
      </geometry>
    </collision>
  </link>
  <joint
    name="EX1J"
    type="prismatic">
    <origin
      xyz="0 0 0.305"
      rpy="1.5708 0 0" />
    <parent
      link="base_link" />
    <child
      link="EX1" />
    <axis
      xyz="1 0 0" />
    <limit
      lower="-0.27"
      upper="0"
      effort="10"
      velocity="0.1" />
    <safety_controller
      k_velocity="0" />
  </joint>
  <link
    name="EX2">
    <inertial>
      <origin
        xyz="0 0.105072444276435 -2.92584085604614E-17"
        rpy="0 0 0" />
      <mass
        value="0.116088794363281" />
      <inertia
        ixx="0.00133800359830616"
        ixy="3.0584065344249E-22"
        ixz="-2.06795153138257E-22"
        iyy="1.15088407194072E-05"
        iyz="4.55114328027992E-21"
        izz="0.00133696119022329" />
    </inertial>
    <visual>
      <origin
        xyz="0 0 0"
        rpy="0 0 0" />
      <geometry>
        <mesh
          filename="package://bot6/meshes/EX2.STL" />
      </geometry>
      <material
        name="">
        <color
          rgba="0.792156862745098 0.819607843137255 0.933333333333333 1" />
      </material>
    </visual>
    <collision>
      <origin
        xyz="0 0 0"
        rpy="0 0 0" />
      <geometry>
        <mesh
          filename="package://bot6/meshes/EX2.STL" />
      </geometry>
    </collision>
  </link>
  <joint
    name="EX2J"
    type="prismatic">
    <origin
      xyz="0.39 0 0"
      rpy="0 0 3.1416" />
    <parent
      link="EX1" />
    <child
      link="EX2" />
    <axis
      xyz="0 1 0" />
    <limit
      lower="-0.198"
      upper="0"
      effort="10"
      velocity="0.1" />
    <safety_controller
      k_velocity="0" />
  </joint>
  <link
    name="CH">
    <inertial>
      <origin
        xyz="1.1102E-16 -0.026528 9.5396E-17"
        rpy="0 0 0" />
      <mass
        value="0.047623" />
      <inertia
        ixx="1.2295E-05"
        ixy="4.8893E-20"
        ixz="9.3058E-22"
        iyy="1.7093E-05"
        iyz="2.3134E-20"
        izz="1.2749E-05" />
    </inertial>
    <visual>
      <origin
        xyz="0 0 0"
        rpy="0 0 0" />
      <geometry>
        <mesh
          filename="package://bot6/meshes/CH.STL" />
      </geometry>
      <material
        name="">
        <color
          rgba="0.79216 0.81961 0.93333 1" />
      </material>
    </visual>
    <collision>
      <origin
        xyz="0 0 0"
        rpy="0 0 0" />
      <geometry>
        <mesh
          filename="package://bot6/meshes/CH.STL" />
      </geometry>
    </collision>
  </link>
  <joint
    name="CHJ"
    type="revolute">
    <origin
      xyz="0 0.2555 0"
      rpy="0 0 3.1416" />
    <parent
      link="EX2" />
    <child
      link="CH" />
    <axis
      xyz="0 0 1" />
    <limit
      lower="-1.5708"
      upper="0"
      effort="10"
      velocity="0.5527" />
    <safety_controller
      k_velocity="0" />
  </joint>
  <link
    name="F1">
    <inertial>
      <origin
        xyz="0.021298 -0.064967 -1.2256E-08"
        rpy="0 0 0" />
      <mass
        value="0.026962" />
      <inertia
        ixx="3.4145E-05"
        ixy="-3.7053E-06"
        ixz="4.0684E-12"
        iyy="7.6085E-06"
        iyz="2.7644E-11"
        izz="3.5528E-05" />
    </inertial>
    <visual>
      <origin
        xyz="0 0 0"
        rpy="0 0 0" />
      <geometry>
        <mesh
          filename="package://bot6/meshes/F1.STL" />
      </geometry>
      <material
        name="">
        <color
          rgba="0.79216 0.81961 0.93333 1" />
      </material>
    </visual>
    <collision>
      <origin
        xyz="0 0 0"
        rpy="0 0 0" />
      <geometry>
        <mesh
          filename="package://bot6/meshes/F1.STL" />
      </geometry>
    </collision>
  </link>
  <joint
    name="F1J"
    type="revolute">
    <origin
      xyz="0.022 -0.037 0"
      rpy="0 0 0" />
    <parent
      link="CH" />
    <child
      link="F1" />
    <axis
      xyz="0 0 1" />
    <limit
      lower="-0.7854"
      upper="0"
      effort="10"
      velocity="0.125" />
    <safety_controller
      k_velocity="0" />
  </joint>
  <link
    name="F2">
    <inertial>
      <origin
        xyz="0.021298 -0.064967 -1.2256E-08"
        rpy="0 0 0" />
      <mass
        value="0.026962" />
      <inertia
        ixx="3.4145E-05"
        ixy="-3.7053E-06"
        ixz="4.0684E-12"
        iyy="7.6085E-06"
        iyz="2.7644E-11"
        izz="3.5528E-05" />
    </inertial>
    <visual>
      <origin
        xyz="0 0 0"
        rpy="0 0 0" />
      <geometry>
        <mesh
          filename="package://bot6/meshes/F2.STL" />
      </geometry>
      <material
        name="">
        <color
          rgba="0.79216 0.81961 0.93333 1" />
      </material>
    </visual>
    <collision>
      <origin
        xyz="0 0 0"
        rpy="0 0 0" />
      <geometry>
        <mesh
          filename="package://bot6/meshes/F2.STL" />
      </geometry>
    </collision>
  </link>
  <joint
    name="F2J"
    type="revolute">
    <origin
      xyz="0 -0.037 -0.022"
      rpy="0 1.5708 0" />
    <parent
      link="CH" />
    <child
      link="F2" />
    <axis
      xyz="0 0 1" />
    <limit
      lower="-0.7854"
      upper="0"
      effort="10"
      velocity="0.125" />
    <safety_controller
      k_velocity="0" />
  </joint>
  <link
    name="F3">
    <inertial>
      <origin
        xyz="0.021298 -0.064967 -1.2256E-08"
        rpy="0 0 0" />
      <mass
        value="0.026962" />
      <inertia
        ixx="3.4145E-05"
        ixy="-3.7053E-06"
        ixz="4.0684E-12"
        iyy="7.6085E-06"
        iyz="2.7644E-11"
        izz="3.5528E-05" />
    </inertial>
    <visual>
      <origin
        xyz="0 0 0"
        rpy="0 0 0" />
      <geometry>
        <mesh
          filename="package://bot6/meshes/F3.STL" />
      </geometry>
      <material
        name="">
        <color
          rgba="0.79216 0.81961 0.93333 1" />
      </material>
    </visual>
    <collision>
      <origin
        xyz="0 0 0"
        rpy="0 0 0" />
      <geometry>
        <mesh
          filename="package://bot6/meshes/F3.STL" />
      </geometry>
    </collision>
  </link>
  <joint
    name="F3J"
    type="revolute">
    <origin
      xyz="-0.022 -0.037 0"
      rpy="-3.1416 0 3.1416" />
    <parent
      link="CH" />
    <child
      link="F3" />
    <axis
      xyz="0 0 1" />
    <limit
      lower="-0.5236"
      upper="0"
      effort="10"
      velocity="0.125" />
    <safety_controller
      k_velocity="0" />
  </joint>
  <link
    name="F4">
    <inertial>
      <origin
        xyz="0.093298 0.064967 -0.022"
        rpy="0 0 0" />
      <mass
        value="0.026962" />
      <inertia
        ixx="3.4145E-05"
        ixy="3.7053E-06"
        ixz="-4.0684E-12"
        iyy="7.6085E-06"
        iyz="2.7644E-11"
        izz="3.5528E-05" />
    </inertial>
    <visual>
      <origin
        xyz="0 0 0"
        rpy="0 0 0" />
      <geometry>
        <mesh
          filename="package://bot6/meshes/F4.STL" />
      </geometry>
      <material
        name="">
        <color
          rgba="0.79216 0.81961 0.93333 1" />
      </material>
    </visual>
    <collision>
      <origin
        xyz="0 0 0"
        rpy="0 0 0" />
      <geometry>
        <mesh
          filename="package://bot6/meshes/F4.STL" />
      </geometry>
    </collision>
  </link>
  <joint
    name="F4J"
    type="revolute">
    <origin
      xyz="0.022 -0.037 -0.05"
      rpy="0 -1.5708 0" />
    <parent
      link="CH" />
    <child
      link="F4" />
    <axis
      xyz="0 0 1" />
    <limit
      lower="0"
      upper="0.7854"
      effort="0"
      velocity="0.125" />
    <safety_controller
      k_velocity="0" />
  </joint>
</robot>