<?xml version="1.0" encoding="utf-8"?>
<!-- This URDF was automatically created by SolidWorks to URDF Exporter! Originally created by Stephen Brawner (brawner@gmail.com) 
     Commit Version: 1.4.4-24-g24328f6  Build Version: 1.5.7084.36479
     For more information, please see http://wiki.ros.org/sw_urdf_exporter -->
<robot
  name="bot2">
  <link
    name="base_link">
    <inertial>
      <origin
        xyz="0.018748 -6.778E-17 0.056734"
        rpy="0 0 0" />
      <mass
        value="3.1992" />
      <inertia
        ixx="0.090721"
        ixy="3.7201E-17"
        ixz="-0.0024282"
        iyy="0.051074"
        iyz="-1.3632E-18"
        izz="0.11593" />
    </inertial>
    <visual>
      <origin
        xyz="0 0 0"
        rpy="0 0 0" />
      <geometry>
        <mesh
          filename="package://bot2/meshes/base_link.STL" />
      </geometry>
      <material
        name="">
        <color
          rgba="0.79216 0.81961 0.93333 1" />
      </material>
    </visual>
    <collision>
      <origin
        xyz="0 0 0"
        rpy="0 0 0" />
      <geometry>
        <mesh
          filename="package://bot2/meshes/base_link.STL" />
      </geometry>
    </collision>
  </link>
  <link
    name="B">
    <inertial>
      <origin
        xyz="0.005 0.1 2.2811E-17"
        rpy="0 0 0" />
      <mass
        value="0.76" />
      <inertia
        ixx="0.011679"
        ixy="1.0729E-20"
        ixz="1.7754E-20"
        iyy="0.0091517"
        iyz="1.7658E-19"
        izz="0.0025397" />
    </inertial>
    <visual>
      <origin
        xyz="0 0 0"
        rpy="0 0 0" />
      <geometry>
        <mesh
          filename="package://bot2/meshes/B.STL" />
      </geometry>
      <material
        name="">
        <color
          rgba="0.79216 0.81961 0.93333 1" />
      </material>
    </visual>
    <collision>
      <origin
        xyz="0 0 0"
        rpy="0 0 0" />
      <geometry>
        <mesh
          filename="package://bot2/meshes/B.STL" />
      </geometry>
    </collision>
  </link>
  <joint
    name="BJ"
    type="prismatic">
    <origin
      xyz="-0.175 0 0.011"
      rpy="1.5707963267949 0 0" />
    <parent
      link="base_link" />
    <child
      link="B" />
    <axis
      xyz="0 1 0" />
    <limit
      lower="-0.15"
      upper="0"
      effort="100"
      velocity="0.1" />
    <safety_controller
      k_velocity="0" />
  </joint>
  <link
    name="FRW">
    <inertial>
      <origin
        xyz="-0.046186 -0.019179 -0.048696"
        rpy="0 0 0" />
      <mass
        value="0.23606" />
      <inertia
        ixx="0.00022129"
        ixy="2.7105E-20"
        ixz="1.9555E-21"
        iyy="0.00022142"
        iyz="-5.846E-08"
        izz="0.00040743" />
    </inertial>
    <visual>
      <origin
        xyz="0 0 0"
        rpy="0 0 0" />
      <geometry>
        <mesh
          filename="package://bot2/meshes/FRW.STL" />
      </geometry>
      <material
        name="">
        <color
          rgba="0.79216 0.81961 0.93333 1" />
      </material>
    </visual>
    <collision>
      <origin
        xyz="0 0 0"
        rpy="0 0 0" />
      <geometry>
        <mesh
          filename="package://bot2/meshes/FRW.STL" />
      </geometry>
    </collision>
  </link>
  <joint
    name="FRWJ"
    type="continuous">
    <origin
      xyz="0.095 -0.17 0.047"
      rpy="1.5708 0.39309 -3.1416" />
    <parent
      link="base_link" />
    <child
      link="FRW" />
    <axis
      xyz="0 0 1" />
    <safety_controller
      k_velocity="0" />
  </joint>
  <link
    name="RRW">
    <inertial>
      <origin
        xyz="0.078517 0.032533 -0.048696"
        rpy="0 0 0" />
      <mass
        value="0.23606" />
      <inertia
        ixx="0.00022129"
        ixy="3.3881E-20"
        ixz="1.1316E-21"
        iyy="0.00022142"
        iyz="-5.846E-08"
        izz="0.00040743" />
    </inertial>
    <visual>
      <origin
        xyz="0 0 0"
        rpy="0 0 0" />
      <geometry>
        <mesh
          filename="package://bot2/meshes/RRW.STL" />
      </geometry>
      <material
        name="">
        <color
          rgba="0.79216 0.81961 0.93333 1" />
      </material>
    </visual>
    <collision>
      <origin
        xyz="0 0 0"
        rpy="0 0 0" />
      <geometry>
        <mesh
          filename="package://bot2/meshes/RRW.STL" />
      </geometry>
    </collision>
  </link>
  <joint
    name="RRWJ"
    type="continuous">
    <origin
      xyz="-0.065 -0.17 0.047"
      rpy="1.5707963267949 0.393094810426521 -3.14159265358979" />
    <parent
      link="base_link" />
    <child
      link="RRW" />
    <axis
      xyz="0 0 1" />
    <safety_controller
      k_velocity="0" />
  </joint>
  <link
    name="FLW">
    <inertial>
      <origin
        xyz="0.05 -2.6617E-05 -0.048696"
        rpy="0 0 0" />
      <mass
        value="0.23606" />
      <inertia
        ixx="0.00022129"
        ixy="-2.1925E-22"
        ixz="1.5305E-20"
        iyy="0.00022142"
        iyz="-5.846E-08"
        izz="0.00040743" />
    </inertial>
    <visual>
      <origin
        xyz="0 0 0"
        rpy="0 0 0" />
      <geometry>
        <mesh
          filename="package://bot2/meshes/FLW.STL" />
      </geometry>
      <material
        name="">
        <color
          rgba="0.79216 0.81961 0.93333 1" />
      </material>
    </visual>
    <collision>
      <origin
        xyz="0 0 0"
        rpy="0 0 0" />
      <geometry>
        <mesh
          filename="package://bot2/meshes/FLW.STL" />
      </geometry>
    </collision>
  </link>
  <joint
    name="FLWJ"
    type="continuous">
    <origin
      xyz="0.095 0.17 0.047"
      rpy="1.5707963267949 0 0" />
    <parent
      link="base_link" />
    <child
      link="FLW" />
    <axis
      xyz="0 0 1" />
    <safety_controller
      k_velocity="0" />
  </joint>
  <link
    name="RLW">
    <inertial>
      <origin
        xyz="-0.085 -2.6617E-05 -0.048696"
        rpy="0 0 0" />
      <mass
        value="0.23606" />
      <inertia
        ixx="0.00022129"
        ixy="-2.1925E-22"
        ixz="1.5305E-20"
        iyy="0.00022142"
        iyz="-5.846E-08"
        izz="0.00040743" />
    </inertial>
    <visual>
      <origin
        xyz="0 0 0"
        rpy="0 0 0" />
      <geometry>
        <mesh
          filename="package://bot2/meshes/RLW.STL" />
      </geometry>
      <material
        name="">
        <color
          rgba="0.79216 0.81961 0.93333 1" />
      </material>
    </visual>
    <collision>
      <origin
        xyz="0 0 0"
        rpy="0 0 0" />
      <geometry>
        <mesh
          filename="package://bot2/meshes/RLW.STL" />
      </geometry>
    </collision>
  </link>
  <joint
    name="RLWJ"
    type="continuous">
    <origin
      xyz="-0.065 0.17 0.047"
      rpy="1.5707963267949 0 0" />
    <parent
      link="base_link" />
    <child
      link="RLW" />
    <axis
      xyz="0 0 1" />
    <safety_controller
      k_velocity="0" />
  </joint>
  <link
    name="RC">
    <inertial>
      <origin
        xyz="0.015 0 0"
        rpy="0 0 0" />
      <mass
        value="0.075" />
      <inertia
        ixx="3.125E-05"
        ixy="-1.6263E-22"
        ixz="4.2352E-22"
        iyy="2.125E-05"
        iyz="-1.0334E-21"
        izz="2.125E-05" />
    </inertial>
    <visual>
      <origin
        xyz="0 0 0"
        rpy="0 0 0" />
      <geometry>
        <mesh
          filename="package://bot2/meshes/RC.STL" />
      </geometry>
      <material
        name="">
        <color
          rgba="0.79216 0.81961 0.93333 1" />
      </material>
    </visual>
    <collision>
      <origin
        xyz="0 0 0"
        rpy="0 0 0" />
      <geometry>
        <mesh
          filename="package://bot2/meshes/RC.STL" />
      </geometry>
    </collision>
  </link>
  <joint
    name="RCJ"
    type="fixed">
    <origin
      xyz="0.03 -0.23 0.125"
      rpy="1.5707963267949 0 1.5707963267949" />
    <parent
      link="base_link" />
    <child
      link="RC" />
    <axis
      xyz="0 0 0" />
    <safety_controller
      k_velocity="0" />
  </joint>
  <link
    name="LC">
    <inertial>
      <origin
        xyz="0.015 0 0"
        rpy="0 0 0" />
      <mass
        value="0.075" />
      <inertia
        ixx="3.125E-05"
        ixy="1.6263E-22"
        ixz="-4.2352E-22"
        iyy="2.125E-05"
        iyz="-1.0334E-21"
        izz="2.125E-05" />
    </inertial>
    <visual>
      <origin
        xyz="0 0 0"
        rpy="0 0 0" />
      <geometry>
        <mesh
          filename="package://bot2/meshes/LC.STL" />
      </geometry>
      <material
        name="">
        <color
          rgba="0.79216 0.81961 0.93333 1" />
      </material>
    </visual>
    <collision>
      <origin
        xyz="0 0 0"
        rpy="0 0 0" />
      <geometry>
        <mesh
          filename="package://bot2/meshes/LC.STL" />
      </geometry>
    </collision>
  </link>
  <joint
    name="LCJ"
    type="fixed">
    <origin
      xyz="0.03 0.23 0.125"
      rpy="-1.5708 0 -1.5708" />
    <parent
      link="base_link" />
    <child
      link="LC" />
    <axis
      xyz="0 0 0" />
    <safety_controller
      k_velocity="0" />
  </joint>
  <link
    name="RA">
    <inertial>
      <origin
        xyz="0.064226 0 0"
        rpy="0 0 0" />
      <mass
        value="0.11493" />
      <inertia
        ixx="1.7546E-05"
        ixy="1.2859E-21"
        ixz="-5.3917E-21"
        iyy="0.0001712"
        iyz="-2.9655E-21"
        izz="0.00017089" />
    </inertial>
    <visual>
      <origin
        xyz="0 0 0"
        rpy="0 0 0" />
      <geometry>
        <mesh
          filename="package://bot2/meshes/RA.STL" />
      </geometry>
      <material
        name="">
        <color
          rgba="0.79216 0.81961 0.93333 1" />
      </material>
    </visual>
    <collision>
      <origin
        xyz="0 0 0"
        rpy="0 0 0" />
      <geometry>
        <mesh
          filename="package://bot2/meshes/RA.STL" />
      </geometry>
    </collision>
  </link>
  <joint
    name="RAJ"
    type="fixed">
    <origin
      xyz="0.175 -0.185 0.055"
      rpy="1.5707963267949 0 0" />
    <parent
      link="base_link" />
    <child
      link="RA" />
    <axis
      xyz="0 0 0" />
    <safety_controller
      k_velocity="0" />
  </joint>
  <link
    name="RF">
    <inertial>
      <origin
        xyz="0.075327 1.3878E-17 0.0052437"
        rpy="0 0 0" />
      <mass
        value="0.24614" />
      <inertia
        ixx="0.00024699"
        ixy="7.1507E-21"
        ixz="-4.7172E-05"
        iyy="0.00069522"
        iyz="3.0946E-20"
        izz="0.00092098" />
    </inertial>
    <visual>
      <origin
        xyz="0 0 0"
        rpy="0 0 0" />
      <geometry>
        <mesh
          filename="package://bot2/meshes/RF.STL" />
      </geometry>
      <material
        name="">
        <color
          rgba="0.79216 0.81961 0.93333 1" />
      </material>
    </visual>
    <collision>
      <origin
        xyz="0 0 0"
        rpy="0 0 0" />
      <geometry>
        <mesh
          filename="package://bot2/meshes/RF.STL" />
      </geometry>
    </collision>
  </link>
  <joint
    name="RFJ"
    type="revolute">
    <origin
      xyz="0.135 0 0"
      rpy="0 0.7854 0" />
    <parent
      link="RA" />
    <child
      link="RF" />
    <axis
      xyz="0 1 0" />
    <limit
      lower="-1.309"
      upper="0.7854"
      effort="100"
      velocity="0.125" />
    <safety_controller
      k_velocity="0" />
  </joint>
  <link
    name="LA">
    <inertial>
      <origin
        xyz="0.064226 0 0"
        rpy="0 0 0" />
      <mass
        value="0.11493" />
      <inertia
        ixx="1.7546E-05"
        ixy="5.6286E-21"
        ixz="2.0529E-21"
        iyy="0.0001712"
        iyz="-2.9655E-21"
        izz="0.00017089" />
    </inertial>
    <visual>
      <origin
        xyz="0 0 0"
        rpy="0 0 0" />
      <geometry>
        <mesh
          filename="package://bot2/meshes/LA.STL" />
      </geometry>
      <material
        name="">
        <color
          rgba="0.79216 0.81961 0.93333 1" />
      </material>
    </visual>
    <collision>
      <origin
        xyz="0 0 0"
        rpy="0 0 0" />
      <geometry>
        <mesh
          filename="package://bot2/meshes/LA.STL" />
      </geometry>
    </collision>
  </link>
  <joint
    name="LAJ"
    type="fixed">
    <origin
      xyz="0.175 0.185 0.055"
      rpy="1.5708 0 0" />
    <parent
      link="base_link" />
    <child
      link="LA" />
    <axis
      xyz="0 0 0" />
    <safety_controller
      k_velocity="0" />
  </joint>
  <link
    name="LF">
    <inertial>
      <origin
        xyz="0.075327 6.9389E-18 0.0052437"
        rpy="0 0 0" />
      <mass
        value="0.24614" />
      <inertia
        ixx="0.00024699"
        ixy="2.2315E-20"
        ixz="-4.7172E-05"
        iyy="0.00069522"
        iyz="-1.2708E-20"
        izz="0.00092098" />
    </inertial>
    <visual>
      <origin
        xyz="0 0 0"
        rpy="0 0 0" />
      <geometry>
        <mesh
          filename="package://bot2/meshes/LF.STL" />
      </geometry>
      <material
        name="">
        <color
          rgba="0.79216 0.81961 0.93333 1" />
      </material>
    </visual>
    <collision>
      <origin
        xyz="0 0 0"
        rpy="0 0 0" />
      <geometry>
        <mesh
          filename="package://bot2/meshes/LF.STL" />
      </geometry>
    </collision>
  </link>
  <joint
    name="LFJ"
    type="revolute">
    <origin
      xyz="0.135 0 0"
      rpy="0 -0.64739213973993 0" />
    <parent
      link="LA" />
    <child
      link="LF" />
    <axis
      xyz="0 1 0" />
    <limit
      lower="-1.30899693899575"
      upper="0.78539816339745"
      effort="100"
      velocity="0.125" />
    <safety_controller
      k_velocity="0" />
  </joint>
  <link
    name="F">
    <inertial>
      <origin
        xyz="0 0 0"
        rpy="0 0 0" />
      <mass
        value="0" />
      <inertia
        ixx="0"
        ixy="0"
        ixz="0"
        iyy="0"
        iyz="0"
        izz="0" />
    </inertial>
    <visual>
      <origin
        xyz="0 0 0"
        rpy="0 0 0" />
      <geometry>
        <mesh
          filename="package://bot2/meshes/F.STL" />
      </geometry>
      <material
        name="">
        <color
          rgba="1 1 1 1" />
      </material>
    </visual>
    <collision>
      <origin
        xyz="0 0 0"
        rpy="0 0 0" />
      <geometry>
        <mesh
          filename="package://bot2/meshes/F.STL" />
      </geometry>
    </collision>
  </link>
  <joint
    name="FJ"
    type="prismatic">
    <origin
      xyz="0.165 0 0.011"
      rpy="1.5707963267949 0 0" />
    <parent
      link="base_link" />
    <child
      link="F" />
    <axis
      xyz="0 1 0" />
    <limit
      lower="-0.18"
      upper="0"
      effort="100"
      velocity="0.1" />
    <safety_controller
      k_velocity="0" />
  </joint>
  <link
    name="FC">
    <inertial>
      <origin
        xyz="0.015 0.01 1.3105E-16"
        rpy="0 0 0" />
      <mass
        value="0.075" />
      <inertia
        ixx="3.125E-05"
        ixy="5.4323E-22"
        ixz="-2.2382E-36"
        iyy="2.125E-05"
        iyz="-1.8149E-21"
        izz="2.125E-05" />
    </inertial>
    <visual>
      <origin
        xyz="0 0 0"
        rpy="0 0 0" />
      <geometry>
        <mesh
          filename="package://bot2/meshes/FC.STL" />
      </geometry>
      <material
        name="">
        <color
          rgba="0.79216 0.81961 0.93333 1" />
      </material>
    </visual>
    <collision>
      <origin
        xyz="0 0 0"
        rpy="0 0 0" />
      <geometry>
        <mesh
          filename="package://bot2/meshes/FC.STL" />
      </geometry>
    </collision>
  </link>
  <joint
    name="FCJ"
    type="fixed">
    <origin
      xyz="0.01 0.265 0"
      rpy="0 0 0" />
    <parent
      link="F" />
    <child
      link="FC" />
    <axis
      xyz="0 0 0" />
    <safety_controller
      k_velocity="0" />
  </joint>
  <link
    name="L">
    <inertial>
      <origin
        xyz="0.025 0.01 8.595E-17"
        rpy="0 0 0" />
      <mass
        value="0.075" />
      <inertia
        ixx="3.125E-05"
        ixy="2.5429E-36"
        ixz="-5.8031E-37"
        iyy="2.125E-05"
        iyz="-2.9499E-21"
        izz="2.125E-05" />
    </inertial>
    <visual>
      <origin
        xyz="0 0 0"
        rpy="0 0 0" />
      <geometry>
        <mesh
          filename="package://bot2/meshes/L.STL" />
      </geometry>
      <material
        name="">
        <color
          rgba="0.79216 0.81961 0.93333 1" />
      </material>
    </visual>
    <collision>
      <origin
        xyz="0 0 0"
        rpy="0 0 0" />
      <geometry>
        <mesh
          filename="package://bot2/meshes/L.STL" />
      </geometry>
    </collision>
  </link>
  <joint
    name="LJ"
    type="fixed">
    <origin
      xyz="0 0.04 0"
      rpy="0 0 0" />
    <parent
      link="F" />
    <child
      link="L" />
    <axis
      xyz="0 0 0" />
    <safety_controller
      k_velocity="0" />
  </joint>
</robot>