<?xml version="1.0" encoding="utf-8"?>
<!-- This URDF was automatically created by SolidWorks to URDF Exporter! Originally created by Stephen Brawner (brawner@gmail.com) 
     Commit Version: 1.4.4-24-g24328f6  Build Version: 1.5.7084.36479
     For more information, please see http://wiki.ros.org/sw_urdf_exporter -->
<robot
  name="bot3">
  <link
    name="base_link">
    <inertial>
      <origin
        xyz="-0.00539024896013846 2.31910501349275E-16 0.0541649239591863"
        rpy="0 0 0" />
      <mass
        value="14.2038893873335" />
      <inertia
        ixx="0.27974817084405"
        ixy="1.99628703435387E-16"
        ixz="0.00733737300937465"
        iyy="0.314594359353927"
        iyz="5.31003671631253E-17"
        izz="0.507038773077114" />
    </inertial>
    <visual>
      <origin
        xyz="0 0 0"
        rpy="0 0 0" />
      <geometry>
        <mesh
          filename="package://bot3/meshes/base_link.STL" />
      </geometry>
      <material
        name="">
        <color
          rgba="0.792156862745098 0.819607843137255 0.933333333333333 1" />
      </material>
    </visual>
    <collision>
      <origin
        xyz="0 0 0"
        rpy="0 0 0" />
      <geometry>
        <mesh
          filename="package://bot3/meshes/base_link.STL" />
      </geometry>
    </collision>
  </link>
  <link
    name="FRW">
    <inertial>
      <origin
        xyz="0 -7.53920386007134E-05 -0.089381031363088"
        rpy="0 0 0" />
      <mass
        value="0.8334016991443" />
      <inertia
        ixx="0.00215743548655978"
        ixy="4.33680868994202E-19"
        ixz="1.75229940963233E-19"
        iyy="0.00216058181623486"
        iyz="-8.55705036383949E-07"
        izz="0.0039286091523943" />
    </inertial>
    <visual>
      <origin
        xyz="0 0 0"
        rpy="0 0 0" />
      <geometry>
        <mesh
          filename="package://bot3/meshes/FRW.STL" />
      </geometry>
      <material
        name="">
        <color
          rgba="0.792156862745098 0.819607843137255 0.933333333333333 1" />
      </material>
    </visual>
    <collision>
      <origin
        xyz="0 0 0"
        rpy="0 0 0" />
      <geometry>
        <mesh
          filename="package://bot3/meshes/FRW.STL" />
      </geometry>
    </collision>
  </link>
  <joint
    name="FRWJ"
    type="continuous">
    <origin
      xyz="0.125 -0.13 -0.025"
      rpy="1.5707963267949 0.39309481042652 -3.14159265358979" />
    <parent
      link="base_link" />
    <child
      link="FRW" />
    <axis
      xyz="0 0 1" />
    <safety_controller
      k_velocity="0" />
  </joint>
  <link
    name="RRW">
    <inertial>
      <origin
        xyz="-2.77555756156289E-17 -7.53920386007342E-05 -0.089381031363088"
        rpy="0 0 0" />
      <mass
        value="0.8334016991443" />
      <inertia
        ixx="0.00215743548655978"
        ixy="2.71050543121376E-19"
        ixz="4.66926912173933E-20"
        iyy="0.00216058181623486"
        iyz="-8.55705036383985E-07"
        izz="0.0039286091523943" />
    </inertial>
    <visual>
      <origin
        xyz="0 0 0"
        rpy="0 0 0" />
      <geometry>
        <mesh
          filename="package://bot3/meshes/RRW.STL" />
      </geometry>
      <material
        name="">
        <color
          rgba="0.792156862745098 0.819607843137255 0.933333333333333 1" />
      </material>
    </visual>
    <collision>
      <origin
        xyz="0 0 0"
        rpy="0 0 0" />
      <geometry>
        <mesh
          filename="package://bot3/meshes/RRW.STL" />
      </geometry>
    </collision>
  </link>
  <joint
    name="RRWJ"
    type="continuous">
    <origin
      xyz="-0.125 -0.13 -0.025"
      rpy="1.5707963267949 0.39309481042652 -3.14159265358979" />
    <parent
      link="base_link" />
    <child
      link="RRW" />
    <axis
      xyz="0 0 1" />
    <safety_controller
      k_velocity="0" />
  </joint>
  <link
    name="FLW">
    <inertial>
      <origin
        xyz="0 -7.53920386007238E-05 -0.0893810313630881"
        rpy="0 0 0" />
      <mass
        value="0.8334016991443" />
      <inertia
        ixx="0.00215743548655978"
        ixy="-8.79635490065067E-21"
        ixz="2.78368928810459E-19"
        iyy="0.00216058181623486"
        iyz="-8.5570503638385E-07"
        izz="0.0039286091523943" />
    </inertial>
    <visual>
      <origin
        xyz="0 0 0"
        rpy="0 0 0" />
      <geometry>
        <mesh
          filename="package://bot3/meshes/FLW.STL" />
      </geometry>
      <material
        name="">
        <color
          rgba="0.792156862745098 0.819607843137255 0.933333333333333 1" />
      </material>
    </visual>
    <collision>
      <origin
        xyz="0 0 0"
        rpy="0 0 0" />
      <geometry>
        <mesh
          filename="package://bot3/meshes/FLW.STL" />
      </geometry>
    </collision>
  </link>
  <joint
    name="FLWJ"
    type="continuous">
    <origin
      xyz="0.125000000000004 0.13 -0.025"
      rpy="1.5707963267949 0 0" />
    <parent
      link="base_link" />
    <child
      link="FLW" />
    <axis
      xyz="0 0 1" />
    <safety_controller
      k_velocity="0" />
  </joint>
  <link
    name="RLW">
    <inertial>
      <origin
        xyz="-1.38777878078145E-17 -7.53920386007238E-05 -0.0893810313630881"
        rpy="0 0 0" />
      <mass
        value="0.8334016991443" />
      <inertia
        ixx="0.00215743548655978"
        ixy="-8.79635490065067E-21"
        ixz="2.78368928810459E-19"
        iyy="0.00216058181623486"
        iyz="-8.5570503638385E-07"
        izz="0.0039286091523943" />
    </inertial>
    <visual>
      <origin
        xyz="0 0 0"
        rpy="0 0 0" />
      <geometry>
        <mesh
          filename="package://bot3/meshes/RLW.STL" />
      </geometry>
      <material
        name="">
        <color
          rgba="0.792156862745098 0.819607843137255 0.933333333333333 1" />
      </material>
    </visual>
    <collision>
      <origin
        xyz="0 0 0"
        rpy="0 0 0" />
      <geometry>
        <mesh
          filename="package://bot3/meshes/RLW.STL" />
      </geometry>
    </collision>
  </link>
  <joint
    name="RLWJ"
    type="continuous">
    <origin
      xyz="-0.124999999999996 0.13 -0.025"
      rpy="1.5707963267949 0 0" />
    <parent
      link="base_link" />
    <child
      link="RLW" />
    <axis
      xyz="0 0 1" />
    <safety_controller
      k_velocity="0" />
  </joint>
  <link
    name="CL">
    <inertial>
      <origin
        xyz="0.015 0 -6.93889390390723E-18"
        rpy="0 0 0" />
      <mass
        value="0.075" />
      <inertia
        ixx="3.125E-05"
        ixy="4.76321900401482E-37"
        ixz="4.23516473627154E-22"
        iyy="2.125E-05"
        iyz="-1.92107072437275E-21"
        izz="2.125E-05" />
    </inertial>
    <visual>
      <origin
        xyz="0 0 0"
        rpy="0 0 0" />
      <geometry>
        <mesh
          filename="package://bot3/meshes/CL.STL" />
      </geometry>
      <material
        name="">
        <color
          rgba="0.792156862745098 0.819607843137255 0.933333333333333 1" />
      </material>
    </visual>
    <collision>
      <origin
        xyz="0 0 0"
        rpy="0 0 0" />
      <geometry>
        <mesh
          filename="package://bot3/meshes/CL.STL" />
      </geometry>
    </collision>
  </link>
  <joint
    name="CLJ"
    type="fixed">
    <origin
      xyz="0.05 0.23 0.125"
      rpy="-1.5707963267949 0 -1.5707963267949" />
    <parent
      link="base_link" />
    <child
      link="CL" />
    <axis
      xyz="0 0 0" />
    <safety_controller
      k_velocity="0" />
  </joint>
  <link
    name="CR">
    <inertial>
      <origin
        xyz="-0.215 0.125 0.0500000000000001"
        rpy="0 0 0" />
      <mass
        value="0.075" />
      <inertia
        ixx="3.125E-05"
        ixy="-1.62630325872826E-22"
        ixz="4.23516473627154E-22"
        iyy="2.125E-05"
        iyz="-1.30556011603463E-21"
        izz="2.125E-05" />
    </inertial>
    <visual>
      <origin
        xyz="0 0 0"
        rpy="0 0 0" />
      <geometry>
        <mesh
          filename="package://bot3/meshes/CR.STL" />
      </geometry>
      <material
        name="">
        <color
          rgba="0.792156862745098 0.819607843137255 0.933333333333333 1" />
      </material>
    </visual>
    <collision>
      <origin
        xyz="0 0 0"
        rpy="0 0 0" />
      <geometry>
        <mesh
          filename="package://bot3/meshes/CR.STL" />
      </geometry>
    </collision>
  </link>
  <joint
    name="CRJ"
    type="fixed">
    <origin
      xyz="0 0 0"
      rpy="1.5707963267949 0 1.5707963267949" />
    <parent
      link="base_link" />
    <child
      link="CR" />
    <axis
      xyz="0 0 0" />
    <safety_controller
      k_velocity="0" />
  </joint>
  <link
    name="FC">
    <inertial>
      <origin
        xyz="0.015 0 -3.18704616733903E-17"
        rpy="0 0 0" />
      <mass
        value="0.075" />
      <inertia
        ixx="3.125E-05"
        ixy="3.52930394689292E-22"
        ixz="-3.52930394689292E-22"
        iyy="2.125E-05"
        iyz="-1.53821183221381E-21"
        izz="2.125E-05" />
    </inertial>
    <visual>
      <origin
        xyz="0 0 0"
        rpy="0 0 0" />
      <geometry>
        <mesh
          filename="package://bot3/meshes/FC.STL" />
      </geometry>
      <material
        name="">
        <color
          rgba="0.792156862745098 0.819607843137255 0.933333333333333 1" />
      </material>
    </visual>
    <collision>
      <origin
        xyz="0 0 0"
        rpy="0 0 0" />
      <geometry>
        <mesh
          filename="package://bot3/meshes/FC.STL" />
      </geometry>
    </collision>
  </link>
  <joint
    name="FCJ"
    type="fixed">
    <origin
      xyz="0.225 0 0.04"
      rpy="1.5707963267949 0 0" />
    <parent
      link="base_link" />
    <child
      link="FC" />
    <axis
      xyz="0 0 0" />
    <safety_controller
      k_velocity="0" />
  </joint>
  <link
    name="EX1">
    <inertial>
      <origin
        xyz="0.161155451186496 0 -7.57413246857604E-18"
        rpy="0 0 0" />
      <mass
        value="0.14636282401554" />
      <inertia
        ixx="1.12799200839636E-05"
        ixy="6.14857749091434E-22"
        ixz="-1.3552621625763E-20"
        iyy="0.00339929403847134"
        iyz="-3.71025841885802E-22"
        izz="0.0033988227995733" />
    </inertial>
    <visual>
      <origin
        xyz="0 0 0"
        rpy="0 0 0" />
      <geometry>
        <mesh
          filename="package://bot3/meshes/EX1.STL" />
      </geometry>
      <material
        name="">
        <color
          rgba="0.792156862745098 0.819607843137255 0.933333333333333 1" />
      </material>
    </visual>
    <collision>
      <origin
        xyz="0 0 0"
        rpy="0 0 0" />
      <geometry>
        <mesh
          filename="package://bot3/meshes/EX1.STL" />
      </geometry>
    </collision>
  </link>
  <joint
    name="EX1J"
    type="prismatic">
    <origin
      xyz="0 0 0.305"
      rpy="1.5708 0 0" />
    <parent
      link="base_link" />
    <child
      link="EX1" />
    <axis
      xyz="1 0 0" />
    <limit
      lower="-0.315"
      upper="-0.1"
      effort="0"
      velocity="0.1" />
    <safety_controller
      k_velocity="0" />
  </joint>
  <link
    name="EX2">
    <inertial>
      <origin
        xyz="4.44089209850063E-16 0.0920741402028054 -1.69838482734986E-17"
        rpy="0 0 0" />
      <mass
        value="0.113544104313874" />
      <inertia
        ixx="0.00122889380118715"
        ixy="-6.75437002260653E-18"
        ixz="-1.55096364853646E-22"
        iyy="1.14057807724062E-05"
        iyz="8.31875062783753E-21"
        izz="0.00122785139310429" />
    </inertial>
    <visual>
      <origin
        xyz="0 0 0"
        rpy="0 0 0" />
      <geometry>
        <mesh
          filename="package://bot3/meshes/EX2.STL" />
      </geometry>
      <material
        name="">
        <color
          rgba="0.792156862745098 0.819607843137255 0.933333333333333 1" />
      </material>
    </visual>
    <collision>
      <origin
        xyz="0 0 0"
        rpy="0 0 0" />
      <geometry>
        <mesh
          filename="package://bot3/meshes/EX2.STL" />
      </geometry>
    </collision>
  </link>
  <joint
    name="EX2J"
    type="prismatic">
    <origin
      xyz="0.39 0 0"
      rpy="0 0 -3.1416" />
    <parent
      link="EX1" />
    <child
      link="EX2" />
    <axis
      xyz="0 1 0" />
    <limit
      lower="-0.19"
      upper="-0.1"
      effort="0"
      velocity="0.1" />
    <safety_controller
      k_velocity="0" />
  </joint>
  <link
    name="CH">
    <inertial>
      <origin
        xyz="0.00500000000000006 -0.0216242094225185 -3.35279381550874E-17"
        rpy="0 0 0" />
      <mass
        value="0.048063273821427" />
      <inertia
        ixx="1.24572997737268E-05"
        ixy="4.65115346063441E-20"
        ixz="1.86115637824402E-21"
        iyy="1.73208224160396E-05"
        iyz="2.84519850944701E-20"
        izz="1.29112365047557E-05" />
    </inertial>
    <visual>
      <origin
        xyz="0 0 0"
        rpy="0 0 0" />
      <geometry>
        <mesh
          filename="package://bot3/meshes/CH.STL" />
      </geometry>
      <material
        name="">
        <color
          rgba="0.792156862745098 0.819607843137255 0.933333333333333 1" />
      </material>
    </visual>
    <collision>
      <origin
        xyz="0 0 0"
        rpy="0 0 0" />
      <geometry>
        <mesh
          filename="package://bot3/meshes/CH.STL" />
      </geometry>
    </collision>
  </link>
  <joint
    name="CHJ"
    type="revolute">
    <origin
      xyz="-0.00499999999999851 0.242500000000001 0"
      rpy="-3.14159265358979 0 0" />
    <parent
      link="EX2" />
    <child
      link="CH" />
    <axis
      xyz="0 0 1" />
    <limit
      lower="0"
      upper="1.6580627893946"
      effort="0"
      velocity="0.5527" />
    <safety_controller
      k_velocity="0" />
  </joint>
  <link
    name="F1">
    <inertial>
      <origin
        xyz="0.034932994986131 -0.0674950984027777 0.00999999691479042"
        rpy="0 0 0" />
      <mass
        value="0.0327956240400983" />
      <inertia
        ixx="6.15283967579236E-05"
        ixy="2.86215799158532E-06"
        ixz="-1.46173231479775E-12"
        iyy="1.18367075887975E-05"
        iyz="9.69053696758723E-12"
        izz="6.56025930550832E-05" />
    </inertial>
    <visual>
      <origin
        xyz="0 0 0"
        rpy="0 0 0" />
      <geometry>
        <mesh
          filename="package://bot3/meshes/F1.STL" />
      </geometry>
      <material
        name="">
        <color
          rgba="0.792156862745098 0.819607843137255 0.933333333333333 1" />
      </material>
    </visual>
    <collision>
      <origin
        xyz="0 0 0"
        rpy="0 0 0" />
      <geometry>
        <mesh
          filename="package://bot3/meshes/F1.STL" />
      </geometry>
    </collision>
  </link>
  <joint
    name="F1J"
    type="continuous">
    <origin
      xyz="-0.00500000000000017 -0.034466812234734 -0.0285765554884929"
      rpy="1.5707963267949 1.41405965199374 1.5707963267949" />
    <parent
      link="CH" />
    <child
      link="F1" />
    <axis
      xyz="0 0 1" />
    <safety_controller
      k_velocity="0" />
  </joint>
  <link
    name="F2">
    <inertial>
      <origin
        xyz="0.0052327318000738 -0.0442174523889779 0.0398034278907389"
        rpy="0 0 0" />
      <mass
        value="0.0655912984650824" />
      <inertia
        ixx="0.00012411457716629"
        ixy="-6.0584261167262E-06"
        ixz="8.01016987477847E-06"
        iyy="5.10590953648672E-05"
        iyz="2.36879809001188E-05"
        izz="0.000102761979754364" />
    </inertial>
    <visual>
      <origin
        xyz="0 0 0"
        rpy="0 0 0" />
      <geometry>
        <mesh
          filename="package://bot3/meshes/F2.STL" />
      </geometry>
      <material
        name="">
        <color
          rgba="0.792156862745098 0.819607843137255 0.933333333333333 1" />
      </material>
    </visual>
    <collision>
      <origin
        xyz="0 0 0"
        rpy="0 0 0" />
      <geometry>
        <mesh
          filename="package://bot3/meshes/F2.STL" />
      </geometry>
    </collision>
  </link>
  <joint
    name="F2J"
    type="continuous">
    <origin
      xyz="-0.00500000000000017 -0.032023443363666 0.0226843374036491"
      rpy="-1.5707963267949 -1.24471431687375 1.5707963267949" />
    <parent
      link="CH" />
    <child
      link="F2" />
    <axis
      xyz="0 0 1" />
    <safety_controller
      k_velocity="0" />
  </joint>
  <link
    name="F3">
    <inertial>
      <origin
        xyz="0.0404031061220904 -0.0707168179872533 -0.0100000040745558"
        rpy="0 0 0" />
      <mass
        value="0.0327956367752749" />
      <inertia
        ixx="6.15284310436947E-05"
        ixy="2.86215707176461E-06"
        ixz="-2.35428656258977E-12"
        iyy="1.18367112940564E-05"
        iyz="1.16010858562191E-11"
        izz="6.56026190945612E-05" />
    </inertial>
    <visual>
      <origin
        xyz="0 0 0"
        rpy="0 0 0" />
      <geometry>
        <mesh
          filename="package://bot3/meshes/F3.STL" />
      </geometry>
      <material
        name="">
        <color
          rgba="0.792156862745098 0.819607843137255 0.933333333333333 1" />
      </material>
    </visual>
    <collision>
      <origin
        xyz="0 0 0"
        rpy="0 0 0" />
      <geometry>
        <mesh
          filename="package://bot3/meshes/F3.STL" />
      </geometry>
    </collision>
  </link>
  <joint
    name="F3J"
    type="continuous">
    <origin
      xyz="-0.00500000000000017 -0.032023443363666 0.0226843374036491"
      rpy="-1.5707963267949 -1.24471431687375 1.5707963267949" />
    <parent
      link="CH" />
    <child
      link="F3" />
    <axis
      xyz="0 0 1" />
    <safety_controller
      k_velocity="0" />
  </joint>
  <link
    name="F4">
    <inertial>
      <origin
        xyz="0.0272741016307185 -0.0556483301030775 -0.0220000041027434"
        rpy="0 0 0" />
      <mass
        value="0.032795637170567" />
      <inertia
        ixx="6.15284320976473E-05"
        ixy="2.86215706096476E-06"
        ixz="-2.38098171486713E-12"
        iyy="1.18367114306114E-05"
        iyz="1.16569927346508E-11"
        izz="6.56026199083052E-05" />
    </inertial>
    <visual>
      <origin
        xyz="0 0 0"
        rpy="0 0 0" />
      <geometry>
        <mesh
          filename="package://bot3/meshes/F4.STL" />
      </geometry>
      <material
        name="">
        <color
          rgba="0.792156862745098 0.819607843137255 0.933333333333333 1" />
      </material>
    </visual>
    <collision>
      <origin
        xyz="0 0 0"
        rpy="0 0 0" />
      <geometry>
        <mesh
          filename="package://bot3/meshes/F4.STL" />
      </geometry>
    </collision>
  </link>
  <joint
    name="F4J"
    type="continuous">
    <origin
      xyz="0.0449999999999998 -0.0419999999999994 0.022"
      rpy="0 0 0.331213027868091" />
    <parent
      link="CH" />
    <child
      link="F4" />
    <axis
      xyz="0 0 1" />
    <safety_controller
      k_velocity="0" />
  </joint>
</robot>