<?xml version="1.0"?>
<robot name="claw">

	<material name="grey">
		<color rgba="0.6 0.6 0.6 1"/>
	</material>
	<material name="black">
		<color rgba="0 0 0 1"/>
	</material>
	<material name="white">
		<color rgba="1 1 1 1"/>
	</material>

	<link name="base_link">
		<collision>
			<origin rpy="0 0 0" xyz="0 0 0"/>
			<geometry>
				<cylinder length="0.26" radius="0.018"/>
			</geometry>
		</collision>
		<visual>
			<origin rpy="0 0 0" xyz="0 0 0"/>
			<geometry>
				<cylinder length="0.26" radius="0.018"/>
			</geometry>
			<material name="grey"/>
		</visual>
		<inertial>
			<mass value="0.1"/>
			<inertia ixx="1.0" ixy="0.0" ixz="0.0" iyy="1.0" iyz="0.0" izz="1.0"/>
		</inertial>
	</link>

	<link name="base_box">
		<collision>
			<origin rpy="0 0 0" xyz="0 0 0"/>
			<geometry>
				<box size="0.25 0.3 0.05"/>
			</geometry>
		</collision>
		<visual>
			<origin rpy="0 0 0" xyz="0 0 0"/>
			<geometry>
				<box size="0.25 0.3 0.05"/>
			</geometry>
			<material name="grey"/>
		</visual>
		<inertial>
			<mass value="1000.0"/>
			<inertia ixx="0.0" ixy="0.0" ixz="0.0" iyy="0.0" iyz="0.0" izz="1.0"/>
		</inertial>
	</link>

	<joint name="base_joint" type="fixed">
		<parent link="base_link"/>
		<child link="base_box"/>
		<origin xyz="0 0 -0.13"/>
	</joint>


	<link name="horizontal">
		<collision>
			<origin rpy="0 1.57075 0" xyz="0 0 0"/>
			<geometry>
				<cylinder length="0.56" radius="0.018"/>
			</geometry>
		</collision>
		<visual>
			<origin rpy="0 1.57075 0" xyz="0 0 0"/>
			<geometry>
				<cylinder length="0.56" radius="0.018"/>
			</geometry>
			<material name="grey"/>
		</visual>
		<inertial>
			<mass value="0.1"/>
			<inertia ixx="1.0" ixy="0.0" ixz="0.0" iyy="1.0" iyz="0.0" izz="1.0"/>
		</inertial>
	</link>

	<joint name="base_to_horizontal" type="prismatic">
		<parent link="base_link"/>
		<child link="horizontal"/>
		<limit effort="1000.0" lower="-0.28" upper="0.28" velocity="0.5"/>
		<origin xyz="0 0 0.13"/>
	</joint>

	<link name="final_arm">
		<collision>
			<origin rpy="0 0 0" xyz="0 0 0"/>
			<geometry>
				<cylinder length="0.27" radius="0.018"/>
			</geometry>
		</collision>
		<visual>
			<origin rpy="0 0 0" xyz="0 0 0"/>
			<geometry>
				<cylinder length="0.27" radius="0.018"/>
			</geometry>
			<material name="grey"/>
		</visual>
		<inertial>
			<mass value="0.1"/>
			<inertia ixx="1.0" ixy="0.0" ixz="0.0" iyy="1.0" iyz="0.0" izz="1.0"/>
		</inertial>
	</link>

	<joint name="horizontal_to_final_arm" type="prismatic">
		<axis xyz="0 0 1"/>
		<parent link="horizontal"/>
		<child link="final_arm"/>
		<limit effort="1000.0" lower="-0.135" upper="0.135" velocity="0.5"/>
		<origin xyz="0.28 0 0"/>
	</joint>

	<link name="left_gripper">
		<collision>
			<origin rpy="0.0 1.57075 0" xyz="0 0 0"/>
			<geometry>
				<mesh filename="package://urdf_tutorial/meshes/l_finger.dae"/>
			</geometry>
		</collision>
		<visual>
			<origin rpy="0.0 1.57075 0" xyz="0 0 0"/>
			<geometry>
				<mesh filename="package://urdf_tutorial/meshes/l_finger.dae"/>
			</geometry>
		</visual>
		<inertial>
			<mass value="0.1"/>
			<inertia ixx="1.0" ixy="0.0" ixz="0.0" iyy="1.0" iyz="0.0" izz="1.0"/>
		</inertial>
	</link>

	<joint name="left_gripper_joint" type="revolute">
		<axis xyz="1 0 0"/>
		<limit effort="1000.0" lower="0.0" upper="1.5" velocity="0.5"/>
		<origin rpy="0 0 0" xyz="0 0 -0.135"/>
		<parent link="final_arm"/>
		<child link="left_gripper"/>
	</joint>

	<link name="right_gripper">
		<collision>
			<origin rpy="-3.1415 1.57075 0" xyz="0 0 0"/>
			<geometry>
				<mesh filename="package://urdf_tutorial/meshes/l_finger.dae"/>
			</geometry>
		</collision>
		<visual>
			<origin rpy="-3.1415 1.57075 0" xyz="0 0 0"/>
			<geometry>
				<mesh filename="package://urdf_tutorial/meshes/l_finger.dae"/>
			</geometry>
		</visual>
		<inertial>
			<mass value="0.1"/>
			<inertia ixx="1.0" ixy="0.0" ixz="0.0" iyy="1.0" iyz="0.0" izz="1.0"/>
		</inertial>
	</link>

	<joint name="right_gripper_joint" type="revolute">
		<axis xyz="-1 0 0"/>
		<limit effort="1000.0" lower="0.0" upper="1.5" velocity="0.5"/>
		<origin rpy="0 0 0" xyz="0 0 -0.135"/>
		<parent link="final_arm"/>
		<child link="right_gripper"/>
		<mimic joint="left_gripper_joint" multiplier="1" offset="0"/>
	</joint>

 <!--Transimission-->

  <transmission name="horizontal_extension_trans" type="SimpleTransmission">
    <type>transmission_interface/SimpleTransmission</type>
    <actuator name="horizontal_extension_motor">
      <mechanicalReduction>1</mechanicalReduction>
    </actuator>
    <joint name="base_to_horizontal">
      <hardwareInterface>PositionJointInterface</hardwareInterface>
    </joint>
  </transmission>

  <transmission name="vertical_extension_trans" type="SimpleTransmission">
    <type>transmission_interface/SimpleTransmission</type>
    <actuator name="vertical_extension_motor">
      <mechanicalReduction>1</mechanicalReduction>
    </actuator>
    <joint name="horizontal_to_final_arm">
      <hardwareInterface>PositionJointInterface</hardwareInterface>
    </joint>
  </transmission>

    <transmission name="gripper_trans" type="SimpleTransmission">
      <type>transmission_interface/SimpleTransmission</type>
      <actuator name="$gripper_motor">
        <mechanicalReduction>1</mechanicalReduction>
      </actuator>
      <joint name="right_gripper_joint">
        <hardwareInterface>PositionJointInterface</hardwareInterface>
      </joint>
    </transmission>

 <!--gazebo plugin-->  
  <gazebo>
    <plugin name="gazebo_ros_control" filename="libgazebo_ros_control.so">
    </plugin>
  </gazebo>

</robot>
