<?xml version="1.0" encoding="utf-8"?>
<!-- This URDF was automatically created by SolidWorks to URDF Exporter! Originally created by Stephen Brawner (brawner@gmail.com) 
     Commit Version: 1.4.4-24-g24328f6  Build Version: 1.5.7084.36479
     For more information, please see http://wiki.ros.org/sw_urdf_exporter -->
<robot
  name="bot15">
  <link
    name="base_link">
    <inertial>
      <origin
        xyz="0.029232 0.047061 -5.6957E-05"
        rpy="0 0 0" />
      <mass
        value="10.067" />
      <inertia
        ixx="0.22006"
        ixy="-0.0014375"
        ixz="-6.9803E-05"
        iyy="0.35668"
        iyz="7.4306E-05"
        izz="0.19974" />
    </inertial>
    <visual>
      <origin
        xyz="0 0 0"
        rpy="0 0 0" />
      <geometry>
        <mesh
          filename="package://bot15/meshes/base_link.STL" />
      </geometry>
      <material
        name="">
        <color
          rgba="0.79216 0.81961 0.93333 1" />
      </material>
    </visual>
    <collision>
      <origin
        xyz="0 0 0"
        rpy="0 0 0" />
      <geometry>
        <mesh
          filename="package://bot15/meshes/base_link.STL" />
      </geometry>
    </collision>
  </link>
  <link
    name="FRW">
    <inertial>
      <origin
        xyz="0 -7.5392E-05 -0.089381"
        rpy="0 0 0" />
      <mass
        value="0.8334" />
      <inertia
        ixx="0.0021574"
        ixy="4.8789E-19"
        ixz="1.7565E-19"
        iyy="0.0021606"
        iyz="-8.5571E-07"
        izz="0.0039286" />
    </inertial>
    <visual>
      <origin
        xyz="0 0 0"
        rpy="0 0 0" />
      <geometry>
        <mesh
          filename="package://bot15/meshes/FRW.STL" />
      </geometry>
      <material
        name="">
        <color
          rgba="0.79216 0.81961 0.93333 1" />
      </material>
    </visual>
    <collision>
      <origin
        xyz="0 0 0"
        rpy="0 0 0" />
      <geometry>
        <mesh
          filename="package://bot15/meshes/FRW.STL" />
      </geometry>
    </collision>
  </link>
  <joint
    name="FRWJ"
    type="continuous">
    <origin
      xyz="0.125 -0.13 -0.025"
      rpy="1.5707963267949 0.39309481042652 -3.14159265358979" />
    <parent
      link="base_link" />
    <child
      link="FRW" />
    <axis
      xyz="0 0 1" />
    <safety_controller
      k_velocity="0" />
  </joint>
  <link
    name="RRW">
    <inertial>
      <origin
        xyz="-2.7756E-17 -7.5392E-05 -0.089381"
        rpy="0 0 0" />
      <mass
        value="0.8334" />
      <inertia
        ixx="0.0021574"
        ixy="6.5052E-19"
        ixz="4.6852E-20"
        iyy="0.0021606"
        iyz="-8.5571E-07"
        izz="0.0039286" />
    </inertial>
    <visual>
      <origin
        xyz="0 0 0"
        rpy="0 0 0" />
      <geometry>
        <mesh
          filename="package://bot15/meshes/RRW.STL" />
      </geometry>
      <material
        name="">
        <color
          rgba="0.79216 0.81961 0.93333 1" />
      </material>
    </visual>
    <collision>
      <origin
        xyz="0 0 0"
        rpy="0 0 0" />
      <geometry>
        <mesh
          filename="package://bot15/meshes/RRW.STL" />
      </geometry>
    </collision>
  </link>
  <joint
    name="RRWJ"
    type="continuous">
    <origin
      xyz="-0.125 -0.13 -0.025"
      rpy="1.5707963267949 0.39309481042652 -3.14159265358979" />
    <parent
      link="base_link" />
    <child
      link="RRW" />
    <axis
      xyz="0 0 1" />
    <safety_controller
      k_velocity="0" />
  </joint>
  <link
    name="FLW">
    <inertial>
      <origin
        xyz="0 -7.5392E-05 -0.089381"
        rpy="0 0 0" />
      <mass
        value="0.8334" />
      <inertia
        ixx="0.0021574"
        ixy="-8.7964E-21"
        ixz="2.7837E-19"
        iyy="0.0021606"
        iyz="-8.5571E-07"
        izz="0.0039286" />
    </inertial>
    <visual>
      <origin
        xyz="0 0 0"
        rpy="0 0 0" />
      <geometry>
        <mesh
          filename="package://bot15/meshes/FLW.STL" />
      </geometry>
      <material
        name="">
        <color
          rgba="0.79216 0.81961 0.93333 1" />
      </material>
    </visual>
    <collision>
      <origin
        xyz="0 0 0"
        rpy="0 0 0" />
      <geometry>
        <mesh
          filename="package://bot15/meshes/FLW.STL" />
      </geometry>
    </collision>
  </link>
  <joint
    name="FLWJ"
    type="continuous">
    <origin
      xyz="0.125000000000004 0.13 -0.025"
      rpy="1.5707963267949 0 0" />
    <parent
      link="base_link" />
    <child
      link="FLW" />
    <axis
      xyz="0 0 1" />
    <safety_controller
      k_velocity="0" />
  </joint>
  <link
    name="RLW">
    <inertial>
      <origin
        xyz="-1.3878E-17 -7.5392E-05 -0.089381"
        rpy="0 0 0" />
      <mass
        value="0.8334" />
      <inertia
        ixx="0.0021574"
        ixy="-8.7964E-21"
        ixz="2.7837E-19"
        iyy="0.0021606"
        iyz="-8.5571E-07"
        izz="0.0039286" />
    </inertial>
    <visual>
      <origin
        xyz="0 0 0"
        rpy="0 0 0" />
      <geometry>
        <mesh
          filename="package://bot15/meshes/RLW.STL" />
      </geometry>
      <material
        name="">
        <color
          rgba="0.79216 0.81961 0.93333 1" />
      </material>
    </visual>
    <collision>
      <origin
        xyz="0 0 0"
        rpy="0 0 0" />
      <geometry>
        <mesh
          filename="package://bot15/meshes/RLW.STL" />
      </geometry>
    </collision>
  </link>
  <joint
    name="RLWJ"
    type="continuous">
    <origin
      xyz="-0.124999999999996 0.13 -0.025"
      rpy="1.5707963267949 0 0" />
    <parent
      link="base_link" />
    <child
      link="RLW" />
    <axis
      xyz="0 0 1" />
    <safety_controller
      k_velocity="0" />
  </joint>
  <link
    name="FC">
    <inertial>
      <origin
        xyz="0.015 -6.9389E-18 -3.7101E-17"
        rpy="0 0 0" />
      <mass
        value="0.075" />
      <inertia
        ixx="3.125E-05"
        ixy="0"
        ixz="0"
        iyy="2.125E-05"
        iyz="-1.9516E-21"
        izz="2.125E-05" />
    </inertial>
    <visual>
      <origin
        xyz="0 0 0"
        rpy="0 0 0" />
      <geometry>
        <mesh
          filename="package://bot15/meshes/FC.STL" />
      </geometry>
      <material
        name="">
        <color
          rgba="0.79216 0.81961 0.93333 1" />
      </material>
    </visual>
    <collision>
      <origin
        xyz="0 0 0"
        rpy="0 0 0" />
      <geometry>
        <mesh
          filename="package://bot15/meshes/FC.STL" />
      </geometry>
    </collision>
  </link>
  <joint
    name="FCJ"
    type="fixed">
    <origin
      xyz="0.225 0 0.04"
      rpy="1.5707963267949 0 0" />
    <parent
      link="base_link" />
    <child
      link="FC" />
    <axis
      xyz="0 0 0" />
    <safety_controller
      k_velocity="0" />
  </joint>
  <link
    name="RC">
    <inertial>
      <origin
        xyz="0.015 0 -6.9389E-18"
        rpy="0 0 0" />
      <mass
        value="0.075" />
      <inertia
        ixx="3.125E-05"
        ixy="-1.6263E-22"
        ixz="4.2352E-22"
        iyy="2.125E-05"
        iyz="-1.3056E-21"
        izz="2.125E-05" />
    </inertial>
    <visual>
      <origin
        xyz="0 0 0"
        rpy="0 0 0" />
      <geometry>
        <mesh
          filename="package://bot15/meshes/RC.STL" />
      </geometry>
      <material
        name="">
        <color
          rgba="0.79216 0.81961 0.93333 1" />
      </material>
    </visual>
    <collision>
      <origin
        xyz="0 0 0"
        rpy="0 0 0" />
      <geometry>
        <mesh
          filename="package://bot15/meshes/RC.STL" />
      </geometry>
    </collision>
  </link>
  <joint
    name="RCJ"
    type="fixed">
    <origin
      xyz="0.0500000000000001 -0.23 0.125"
      rpy="1.5707963267949 0 1.5707963267949" />
    <parent
      link="base_link" />
    <child
      link="RC" />
    <axis
      xyz="0 0 0" />
    <safety_controller
      k_velocity="0" />
  </joint>
  <link
    name="LC">
    <inertial>
      <origin
        xyz="0.015 0 6.9389E-18"
        rpy="0 0 0" />
      <mass
        value="0.075" />
      <inertia
        ixx="3.125E-05"
        ixy="-1.6263E-22"
        ixz="4.2352E-22"
        iyy="2.125E-05"
        iyz="6.5052E-22"
        izz="2.125E-05" />
    </inertial>
    <visual>
      <origin
        xyz="0 0 0"
        rpy="0 0 0" />
      <geometry>
        <mesh
          filename="package://bot15/meshes/LC.STL" />
      </geometry>
      <material
        name="">
        <color
          rgba="0.79216 0.81961 0.93333 1" />
      </material>
    </visual>
    <collision>
      <origin
        xyz="0 0 0"
        rpy="0 0 0" />
      <geometry>
        <mesh
          filename="package://bot15/meshes/LC.STL" />
      </geometry>
    </collision>
  </link>
  <joint
    name="LCJ"
    type="fixed">
    <origin
      xyz="0.05 0.2 0.125"
      rpy="1.5707963267949 0 1.5707963267949" />
    <parent
      link="base_link" />
    <child
      link="LC" />
    <axis
      xyz="0 0 0" />
    <safety_controller
      k_velocity="0" />
  </joint>
  <link
    name="B">
    <inertial>
      <origin
        xyz="0.00625 0.099085 -2.2196E-17"
        rpy="0 0 0" />
      <mass
        value="0.92892" />
      <inertia
        ixx="0.013926"
        ixy="-1.0304E-36"
        ixz="3.5706E-20"
        iyy="0.010898"
        iyz="-5.0118E-19"
        izz="0.0030521" />
    </inertial>
    <visual>
      <origin
        xyz="0 0 0"
        rpy="0 0 0" />
      <geometry>
        <mesh
          filename="package://bot15/meshes/B.STL" />
      </geometry>
      <material
        name="">
        <color
          rgba="0.79216 0.81961 0.93333 1" />
      </material>
    </visual>
    <collision>
      <origin
        xyz="0 0 0"
        rpy="0 0 0" />
      <geometry>
        <mesh
          filename="package://bot15/meshes/B.STL" />
      </geometry>
    </collision>
  </link>
  <joint
    name="BJ"
    type="prismatic">
    <origin
      xyz="-0.225 0 0.0228173180014822"
      rpy="1.5707963267949 0 0" />
    <parent
      link="base_link" />
    <child
      link="B" />
    <axis
      xyz="0 1 0" />
    <limit
      lower="-0.15"
      upper="0"
      effort="100"
      velocity="0.1" />
    <safety_controller
      k_velocity="0" />
  </joint>
  <link
    name="EP1">
    <inertial>
      <origin
        xyz="0.1725 0 3.7297E-17"
        rpy="0 0 0" />
      <mass
        value="0.22" />
      <inertia
        ixx="1.4667E-05"
        ixy="0"
        ixz="-5.2475E-21"
        iyy="0.0055532"
        iyz="1.2721E-22"
        izz="0.0055532" />
    </inertial>
    <visual>
      <origin
        xyz="0 0 0"
        rpy="0 0 0" />
      <geometry>
        <mesh
          filename="package://bot15/meshes/EP1.STL" />
      </geometry>
      <material
        name="">
        <color
          rgba="0.79216 0.81961 0.93333 1" />
      </material>
    </visual>
    <collision>
      <origin
        xyz="0 0 0"
        rpy="0 0 0" />
      <geometry>
        <mesh
          filename="package://bot15/meshes/EP1.STL" />
      </geometry>
    </collision>
  </link>
  <joint
    name="EP1J"
    type="prismatic">
    <origin
      xyz="0 0.00500000000000016 0.33"
      rpy="1.5707963267949 0 0" />
    <parent
      link="base_link" />
    <child
      link="EP1" />
    <axis
      xyz="1 0 0" />
    <limit
      lower="0"
      upper="0.35"
      effort="100"
      velocity="0.1" />
    <safety_controller
      k_velocity="0" />
  </joint>
  <link
    name="EP2">
    <inertial>
      <origin
        xyz="0 -0.14 -1.1362E-16"
        rpy="0 0 0" />
      <mass
        value="0.12" />
      <inertia
        ixx="0.000904"
        ixy="-2.2588E-21"
        ixz="-3.3018E-22"
        iyy="8E-06"
        iyz="2.1176E-21"
        izz="0.000904" />
    </inertial>
    <visual>
      <origin
        xyz="0 0 0"
        rpy="0 0 0" />
      <geometry>
        <mesh
          filename="package://bot15/meshes/EP2.STL" />
      </geometry>
      <material
        name="">
        <color
          rgba="0.79216 0.81961 0.93333 1" />
      </material>
    </visual>
    <collision>
      <origin
        xyz="0 0 0"
        rpy="0 0 0" />
      <geometry>
        <mesh
          filename="package://bot15/meshes/EP2.STL" />
      </geometry>
    </collision>
  </link>
  <joint
    name="EP2J"
    type="prismatic">
    <origin
      xyz="0.4575 0 0"
      rpy="0 0 0" />
    <parent
      link="EP1" />
    <child
      link="EP2" />
    <axis
      xyz="0 1 0" />
    <limit
      lower="-0.23"
      upper="0"
      effort="100"
      velocity="0.1" />
    <safety_controller
      k_velocity="0" />
  </joint>
  <link
    name="CH">
    <inertial>
      <origin
        xyz="-1.1102E-16 -0.008042 -1.8215E-17"
        rpy="0 0 0" />
      <mass
        value="0.026574" />
      <inertia
        ixx="4.7597E-06"
        ixy="-2.0809E-21"
        ixz="-1.4565E-21"
        iyy="7.4378E-06"
        iyz="-4.8449E-21"
        izz="4.7597E-06" />
    </inertial>
    <visual>
      <origin
        xyz="0 0 0"
        rpy="0 0 0" />
      <geometry>
        <mesh
          filename="package://bot15/meshes/CH.STL" />
      </geometry>
      <material
        name="">
        <color
          rgba="0.79216 0.81961 0.93333 1" />
      </material>
    </visual>
    <collision>
      <origin
        xyz="0 0 0"
        rpy="0 0 0" />
      <geometry>
        <mesh
          filename="package://bot15/meshes/CH.STL" />
      </geometry>
    </collision>
  </link>
  <joint
    name="CHJ"
    type="fixed">
    <origin
      xyz="0 -0.295 0"
      rpy="3.14159265358979 0 3.14159265358979" />
    <parent
      link="EP2" />
    <child
      link="CH" />
    <axis
      xyz="0 0 0" />
    <safety_controller
      k_velocity="0" />
  </joint>
  <link
    name="F1">
    <inertial>
      <origin
        xyz="0.021298 -0.064967 5.5279E-08"
        rpy="0 0 0" />
      <mass
        value="0.026963" />
      <inertia
        ixx="3.4145E-05"
        ixy="-3.7053E-06"
        ixz="1.4921E-11"
        iyy="7.6085E-06"
        iyz="-5.0153E-11"
        izz="3.5529E-05" />
    </inertial>
    <visual>
      <origin
        xyz="0 0 0"
        rpy="0 0 0" />
      <geometry>
        <mesh
          filename="package://bot15/meshes/F1.STL" />
      </geometry>
      <material
        name="">
        <color
          rgba="0.79216 0.81961 0.93333 1" />
      </material>
    </visual>
    <collision>
      <origin
        xyz="0 0 0"
        rpy="0 0 0" />
      <geometry>
        <mesh
          filename="package://bot15/meshes/F1.STL" />
      </geometry>
    </collision>
  </link>
  <joint
    name="F1J"
    type="revolute">
    <origin
      xyz="-0.0143205080756888 -0.017 0"
      rpy="3.14159265358979 0 2.87979326579064" />
    <parent
      link="CH" />
    <child
      link="F1" />
    <axis
      xyz="0 0 1" />
    <limit
      lower="-1.0471975511966"
      upper="0"
      effort="100"
      velocity="0.125" />
    <safety_controller
      k_velocity="0" />
  </joint>
  <link
    name="F2">
    <inertial>
      <origin
        xyz="0.021298 -0.064967 6.1784E-08"
        rpy="0 0 0" />
      <mass
        value="0.026963" />
      <inertia
        ixx="3.4145E-05"
        ixy="-3.7053E-06"
        ixz="1.4729E-11"
        iyy="7.6085E-06"
        iyz="-5.8707E-11"
        izz="3.5528E-05" />
    </inertial>
    <visual>
      <origin
        xyz="0 0 0"
        rpy="0 0 0" />
      <geometry>
        <mesh
          filename="package://bot15/meshes/F2.STL" />
      </geometry>
      <material
        name="">
        <color
          rgba="0.79216 0.81961 0.93333 1" />
      </material>
    </visual>
    <collision>
      <origin
        xyz="0 0 0"
        rpy="0 0 0" />
      <geometry>
        <mesh
          filename="package://bot15/meshes/F2.STL" />
      </geometry>
    </collision>
  </link>
  <joint
    name="F2J"
    type="revolute">
    <origin
      xyz="0.00716025403784548 -0.017 -0.0124019237886468"
      rpy="0.421429094018827 0.990894238270136 0.491952211341743" />
    <parent
      link="CH" />
    <child
      link="F2" />
    <axis
      xyz="0 0 1" />
    <limit
      lower="0"
      upper="1.0471975511966"
      effort="100"
      velocity="0.125" />
    <safety_controller
      k_velocity="0" />
  </joint>
  <link
    name="F3">
    <inertial>
      <origin
        xyz="0.03073 -0.085094 4.5374E-08"
        rpy="0 0 0" />
      <mass
        value="0.026963" />
      <inertia
        ixx="3.4145E-05"
        ixy="-3.7053E-06"
        ixz="1.3008E-11"
        iyy="7.6085E-06"
        iyz="-4.7018E-11"
        izz="3.5529E-05" />
    </inertial>
    <visual>
      <origin
        xyz="0 0 0"
        rpy="0 0 0" />
      <geometry>
        <mesh
          filename="package://bot15/meshes/F3.STL" />
      </geometry>
      <material
        name="">
        <color
          rgba="0.79216 0.81961 0.93333 1" />
      </material>
    </visual>
    <collision>
      <origin
        xyz="0 0 0"
        rpy="0 0 0" />
      <geometry>
        <mesh
          filename="package://bot15/meshes/F3.STL" />
      </geometry>
    </collision>
  </link>
  <joint
    name="F3J"
    type="revolute">
    <origin
      xyz="0 0 0"
      rpy="-0.4214290940189 -0.990894238270186 0.491952211341808" />
    <parent
      link="CH" />
    <child
      link="F3" />
    <axis
      xyz="0 0 1" />
    <limit
      lower="-1.0471975511966"
      upper="0"
      effort="100"
      velocity="0.125" />
    <safety_controller
      k_velocity="0" />
  </joint>
</robot>