<?xml version="1.0" encoding="utf-8"?>
<!-- This URDF was automatically created by SolidWorks to URDF Exporter! Originally created by Stephen Brawner (brawner@gmail.com) 
     Commit Version: 1.4.4-24-g24328f6  Build Version: 1.5.7084.36479
     For more information, please see http://wiki.ros.org/sw_urdf_exporter -->
<robot
  name="bot7_2">
  <link
    name="base_link">
    <inertial>
      <origin
        xyz="0.0072784 2.3614E-16 0.05469"
        rpy="0 0 0" />
      <mass
        value="11.125" />
      <inertia
        ixx="0.24112"
        ixy="1.9249E-16"
        ixz="0.015551"
        iyy="0.26315"
        iyz="7.7546E-17"
        izz="0.42071" />
    </inertial>
    <visual>
      <origin
        xyz="0 0 0"
        rpy="0 0 0" />
      <geometry>
        <mesh
          filename="package://bot7_2/meshes/base_link.STL" />
      </geometry>
      <material
        name="">
        <color
          rgba="0.79216 0.81961 0.93333 1" />
      </material>
    </visual>
    <collision>
      <origin
        xyz="0 0 0"
        rpy="0 0 0" />
      <geometry>
        <mesh
          filename="package://bot7_2/meshes/base_link.STL" />
      </geometry>
    </collision>
  </link>
  <link
    name="FRW">
    <inertial>
      <origin
        xyz="0 -7.5392E-05 -0.089381"
        rpy="0 0 0" />
      <mass
        value="0.8334" />
      <inertia
        ixx="0.0021574"
        ixy="1.6263E-19"
        ixz="-8.4703E-21"
        iyy="0.0021606"
        iyz="-8.5571E-07"
        izz="0.0039286" />
    </inertial>
    <visual>
      <origin
        xyz="0 0 0"
        rpy="0 0 0" />
      <geometry>
        <mesh
          filename="package://bot7_2/meshes/FRW.STL" />
      </geometry>
      <material
        name="">
        <color
          rgba="0.79216 0.81961 0.93333 1" />
      </material>
    </visual>
    <collision>
      <origin
        xyz="0 0 0"
        rpy="0 0 0" />
      <geometry>
        <mesh
          filename="package://bot7_2/meshes/FRW.STL" />
      </geometry>
    </collision>
  </link>
  <joint
    name="FRWJ"
    type="continuous">
    <origin
      xyz="0.125 -0.13 -0.025"
      rpy="1.5708 0.39309 -3.1416" />
    <parent
      link="base_link" />
    <child
      link="FRW" />
    <axis
      xyz="0 0 1" />
    <safety_controller
      k_velocity="0" />
  </joint>
  <link
    name="FLW">
    <inertial>
      <origin
        xyz="0 -7.5392E-05 -0.089381"
        rpy="0 0 0" />
      <mass
        value="0.8334" />
      <inertia
        ixx="0.0021574"
        ixy="-8.7964E-21"
        ixz="2.7837E-19"
        iyy="0.0021606"
        iyz="-8.5571E-07"
        izz="0.0039286" />
    </inertial>
    <visual>
      <origin
        xyz="0 0 0"
        rpy="0 0 0" />
      <geometry>
        <mesh
          filename="package://bot7_2/meshes/FLW.STL" />
      </geometry>
      <material
        name="">
        <color
          rgba="0.79216 0.81961 0.93333 1" />
      </material>
    </visual>
    <collision>
      <origin
        xyz="0 0 0"
        rpy="0 0 0" />
      <geometry>
        <mesh
          filename="package://bot7_2/meshes/FLW.STL" />
      </geometry>
    </collision>
  </link>
  <joint
    name="FLWJ"
    type="continuous">
    <origin
      xyz="0.125 0.13 -0.025"
      rpy="1.5708 0 0" />
    <parent
      link="base_link" />
    <child
      link="FLW" />
    <axis
      xyz="0 0 1" />
    <safety_controller
      k_velocity="0" />
  </joint>
  <link
    name="RRW">
    <inertial>
      <origin
        xyz="-2.7756E-17 -7.5392E-05 -0.089381"
        rpy="0 0 0" />
      <mass
        value="0.8334" />
      <inertia
        ixx="0.0021574"
        ixy="6.5052E-19"
        ixz="4.6799E-20"
        iyy="0.0021606"
        iyz="-8.5571E-07"
        izz="0.0039286" />
    </inertial>
    <visual>
      <origin
        xyz="0 0 0"
        rpy="0 0 0" />
      <geometry>
        <mesh
          filename="package://bot7_2/meshes/RRW.STL" />
      </geometry>
      <material
        name="">
        <color
          rgba="0.79216 0.81961 0.93333 1" />
      </material>
    </visual>
    <collision>
      <origin
        xyz="0 0 0"
        rpy="0 0 0" />
      <geometry>
        <mesh
          filename="package://bot7_2/meshes/RRW.STL" />
      </geometry>
    </collision>
  </link>
  <joint
    name="RRWJ"
    type="continuous">
    <origin
      xyz="-0.125 -0.13 -0.025"
      rpy="1.5708 0.39309 -3.1416" />
    <parent
      link="base_link" />
    <child
      link="RRW" />
    <axis
      xyz="0 0 1" />
    <safety_controller
      k_velocity="0" />
  </joint>
  <link
    name="RLW">
    <inertial>
      <origin
        xyz="-1.3878E-17 -7.5392E-05 -0.089381"
        rpy="0 0 0" />
      <mass
        value="0.8334" />
      <inertia
        ixx="0.0021574"
        ixy="-8.7964E-21"
        ixz="2.7837E-19"
        iyy="0.0021606"
        iyz="-8.5571E-07"
        izz="0.0039286" />
    </inertial>
    <visual>
      <origin
        xyz="0 0 0"
        rpy="0 0 0" />
      <geometry>
        <mesh
          filename="package://bot7_2/meshes/RLW.STL" />
      </geometry>
      <material
        name="">
        <color
          rgba="0.79216 0.81961 0.93333 1" />
      </material>
    </visual>
    <collision>
      <origin
        xyz="0 0 0"
        rpy="0 0 0" />
      <geometry>
        <mesh
          filename="package://bot7_2/meshes/RLW.STL" />
      </geometry>
    </collision>
  </link>
  <joint
    name="RLWJ"
    type="continuous">
    <origin
      xyz="-0.125 0.13 -0.025"
      rpy="1.5708 0 0" />
    <parent
      link="base_link" />
    <child
      link="RLW" />
    <axis
      xyz="0 0 1" />
    <safety_controller
      k_velocity="0" />
  </joint>
  <link
    name="LC">
    <inertial>
      <origin
        xyz="0.015 0 0"
        rpy="0 0 0" />
      <mass
        value="0.075" />
      <inertia
        ixx="3.125E-05"
        ixy="-1.6263E-22"
        ixz="4.2352E-22"
        iyy="2.125E-05"
        iyz="-1.3056E-21"
        izz="2.125E-05" />
    </inertial>
    <visual>
      <origin
        xyz="0 0 0"
        rpy="0 0 0" />
      <geometry>
        <mesh
          filename="package://bot7_2/meshes/LC.STL" />
      </geometry>
      <material
        name="">
        <color
          rgba="0.79216 0.81961 0.93333 1" />
      </material>
    </visual>
    <collision>
      <origin
        xyz="0 0 0"
        rpy="0 0 0" />
      <geometry>
        <mesh
          filename="package://bot7_2/meshes/LC.STL" />
      </geometry>
    </collision>
  </link>
  <joint
    name="LCJ"
    type="fixed">
    <origin
      xyz="0.05 0.2 0.125"
      rpy="1.5708 0 1.5708" />
    <parent
      link="base_link" />
    <child
      link="LC" />
    <axis
      xyz="0 0 0" />
    <safety_controller
      k_velocity="0" />
  </joint>
  <link
    name="FC">
    <inertial>
      <origin
        xyz="0.015 0 -1.0674E-16"
        rpy="0 0 0" />
      <mass
        value="0.075" />
      <inertia
        ixx="3.125E-05"
        ixy="-9.1835E-38"
        ixz="4.2352E-22"
        iyy="2.125E-05"
        iyz="-3.3633E-21"
        izz="2.125E-05" />
    </inertial>
    <visual>
      <origin
        xyz="0 0 0"
        rpy="0 0 0" />
      <geometry>
        <mesh
          filename="package://bot7_2/meshes/FC.STL" />
      </geometry>
      <material
        name="">
        <color
          rgba="0.79216 0.81961 0.93333 1" />
      </material>
    </visual>
    <collision>
      <origin
        xyz="0 0 0"
        rpy="0 0 0" />
      <geometry>
        <mesh
          filename="package://bot7_2/meshes/FC.STL" />
      </geometry>
    </collision>
  </link>
  <joint
    name="FCJ"
    type="fixed">
    <origin
      xyz="0.225 0 0.04"
      rpy="1.5708 0 0" />
    <parent
      link="base_link" />
    <child
      link="FC" />
    <axis
      xyz="0 0 0" />
    <safety_controller
      k_velocity="0" />
  </joint>
  <link
    name="RC">
    <inertial>
      <origin
        xyz="-0.415 0 7.6328E-17"
        rpy="0 0 0" />
      <mass
        value="0.075" />
      <inertia
        ixx="3.125E-05"
        ixy="-1.6263E-22"
        ixz="4.2352E-22"
        iyy="2.125E-05"
        iyz="-1.3056E-21"
        izz="2.125E-05" />
    </inertial>
    <visual>
      <origin
        xyz="0 0 0"
        rpy="0 0 0" />
      <geometry>
        <mesh
          filename="package://bot7_2/meshes/RC.STL" />
      </geometry>
      <material
        name="">
        <color
          rgba="0.79216 0.81961 0.93333 1" />
      </material>
    </visual>
    <collision>
      <origin
        xyz="0 0 0"
        rpy="0 0 0" />
      <geometry>
        <mesh
          filename="package://bot7_2/meshes/RC.STL" />
      </geometry>
    </collision>
  </link>
  <joint
    name="RCJ"
    type="fixed">
    <origin
      xyz="0.05 0.2 0.125"
      rpy="1.5708 0 1.5708" />
    <parent
      link="base_link" />
    <child
      link="RC" />
    <axis
      xyz="0 0 0" />
    <safety_controller
      k_velocity="0" />
  </joint>
  <link
    name="EP1">
    <inertial>
      <origin
        xyz="0.12296 0 2.4032E-16"
        rpy="0 0 0" />
      <mass
        value="0.17181" />
      <inertia
        ixx="1.2311E-05"
        ixy="-1.1908E-20"
        ixz="-1.423E-20"
        iyy="0.0057549"
        iyz="-4.5234E-22"
        izz="0.0057544" />
    </inertial>
    <visual>
      <origin
        xyz="0 0 0"
        rpy="0 0 0" />
      <geometry>
        <mesh
          filename="package://bot7_2/meshes/EP1.STL" />
      </geometry>
      <material
        name="">
        <color
          rgba="0.79216 0.81961 0.93333 1" />
      </material>
    </visual>
    <collision>
      <origin
        xyz="0 0 0"
        rpy="0 0 0" />
      <geometry>
        <mesh
          filename="package://bot7_2/meshes/EP1.STL" />
      </geometry>
    </collision>
  </link>
  <joint
    name="EP1J"
    type="prismatic">
    <origin
      xyz="0 0 0.305"
      rpy="1.5708 0 0" />
    <parent
      link="base_link" />
    <child
      link="EP1" />
    <axis
      xyz="1 0 0" />
    <limit
      lower="-0.34"
      upper="0"
      effort="10"
      velocity="0.1" />
    <safety_controller
      k_velocity="0" />
  </joint>
  <link
    name="EP2">
    <inertial>
      <origin
        xyz="1.6653E-16 0.10207 -1.356E-17"
        rpy="0 0 0" />
      <mass
        value="0.11609" />
      <inertia
        ixx="0.001338"
        ixy="-1.6107E-22"
        ixz="-2.5849E-22"
        iyy="1.1509E-05"
        iyz="-1.0325E-20"
        izz="0.001337" />
    </inertial>
    <visual>
      <origin
        xyz="0 0 0"
        rpy="0 0 0" />
      <geometry>
        <mesh
          filename="package://bot7_2/meshes/EP2.STL" />
      </geometry>
      <material
        name="">
        <color
          rgba="0.79216 0.81961 0.93333 1" />
      </material>
    </visual>
    <collision>
      <origin
        xyz="0 0 0"
        rpy="0 0 0" />
      <geometry>
        <mesh
          filename="package://bot7_2/meshes/EP2.STL" />
      </geometry>
    </collision>
  </link>
  <joint
    name="EP2J"
    type="prismatic">
    <origin
      xyz="0.4025 0 0"
      rpy="0 0 3.1416" />
    <parent
      link="EP1" />
    <child
      link="EP2" />
    <axis
      xyz="0 1 0" />
    <limit
      lower="-0.195"
      upper="0"
      effort="10"
      velocity="0.1" />
    <safety_controller
      k_velocity="0" />
  </joint>
  <link
    name="CH">
    <inertial>
      <origin
        xyz="-5.5511E-17 -0.026916 -2.3329E-16"
        rpy="0 0 0" />
      <mass
        value="0.033597" />
      <inertia
        ixx="5.6903E-06"
        ixy="-6.4427E-21"
        ixz="-4.0115E-21"
        iyy="8.1088E-06"
        iyz="-4.5568E-21"
        izz="6.3442E-06" />
    </inertial>
    <visual>
      <origin
        xyz="0 0 0"
        rpy="0 0 0" />
      <geometry>
        <mesh
          filename="package://bot7_2/meshes/CH.STL" />
      </geometry>
      <material
        name="">
        <color
          rgba="0.79216 0.81961 0.93333 1" />
      </material>
    </visual>
    <collision>
      <origin
        xyz="0 0 0"
        rpy="0 0 0" />
      <geometry>
        <mesh
          filename="package://bot7_2/meshes/CH.STL" />
      </geometry>
    </collision>
  </link>
  <joint
    name="CHJ"
    type="revolute">
    <origin
      xyz="0 0.2525 0"
      rpy="3.1416 0 0" />
    <parent
      link="EP2" />
    <child
      link="CH" />
    <axis
      xyz="0 0 1" />
    <limit
      lower="-0.7854"
      upper="0"
      effort="10"
      velocity="0.125" />
    <safety_controller
      k_velocity="0" />
  </joint>
  <link
    name="F1">
    <inertial>
      <origin
        xyz="0.021298 -0.064967 4.5374E-08"
        rpy="0 0 0" />
      <mass
        value="0.026963" />
      <inertia
        ixx="3.4145E-05"
        ixy="-3.7053E-06"
        ixz="1.3008E-11"
        iyy="7.6085E-06"
        iyz="-4.7018E-11"
        izz="3.5529E-05" />
    </inertial>
    <visual>
      <origin
        xyz="0 0 0"
        rpy="0 0 0" />
      <geometry>
        <mesh
          filename="package://bot7_2/meshes/F1.STL" />
      </geometry>
      <material
        name="">
        <color
          rgba="0.79216 0.81961 0.93333 1" />
      </material>
    </visual>
    <collision>
      <origin
        xyz="0 0 0"
        rpy="0 0 0" />
      <geometry>
        <mesh
          filename="package://bot7_2/meshes/F1.STL" />
      </geometry>
    </collision>
  </link>
  <joint
    name="F1J"
    type="revolute">
    <origin
      xyz="0.0071603 -0.042 0.012402"
      rpy="-0.42143 -0.99089 0.49195" />
    <parent
      link="CH" />
    <child
      link="F1" />
    <axis
      xyz="0 0 1" />
    <limit
      lower="0"
      upper="1.0472"
      effort="10"
      velocity="0.125" />
    <safety_controller
      k_velocity="0" />
  </joint>
  <link
    name="F2">
    <inertial>
      <origin
        xyz="0.021298 -0.064967 5.5279E-08"
        rpy="0 0 0" />
      <mass
        value="0.026963" />
      <inertia
        ixx="3.4145E-05"
        ixy="-3.7053E-06"
        ixz="1.4921E-11"
        iyy="7.6085E-06"
        iyz="-5.0153E-11"
        izz="3.5529E-05" />
    </inertial>
    <visual>
      <origin
        xyz="0 0 0"
        rpy="0 0 0" />
      <geometry>
        <mesh
          filename="package://bot7_2/meshes/F2.STL" />
      </geometry>
      <material
        name="">
        <color
          rgba="0.79216 0.81961 0.93333 1" />
      </material>
    </visual>
    <collision>
      <origin
        xyz="0 0 0"
        rpy="0 0 0" />
      <geometry>
        <mesh
          filename="package://bot7_2/meshes/F2.STL" />
      </geometry>
    </collision>
  </link>
  <joint
    name="F2J"
    type="revolute">
    <origin
      xyz="-0.014321 -0.042 0"
      rpy="3.1416 0 2.8798" />
    <parent
      link="CH" />
    <child
      link="F2" />
    <axis
      xyz="0 0 1" />
    <limit
      lower="0"
      upper="1.0472"
      effort="10"
      velocity="0.125" />
    <safety_controller
      k_velocity="0" />
  </joint>
  <link
    name="F3">
    <inertial>
      <origin
        xyz="0.021298 -0.064967 6.1784E-08"
        rpy="0 0 0" />
      <mass
        value="0.026963" />
      <inertia
        ixx="3.4145E-05"
        ixy="-3.7053E-06"
        ixz="1.4729E-11"
        iyy="7.6085E-06"
        iyz="-5.8707E-11"
        izz="3.5528E-05" />
    </inertial>
    <visual>
      <origin
        xyz="0 0 0"
        rpy="0 0 0" />
      <geometry>
        <mesh
          filename="package://bot7_2/meshes/F3.STL" />
      </geometry>
      <material
        name="">
        <color
          rgba="0.79216 0.81961 0.93333 1" />
      </material>
    </visual>
    <collision>
      <origin
        xyz="0 0 0"
        rpy="0 0 0" />
      <geometry>
        <mesh
          filename="package://bot7_2/meshes/F3.STL" />
      </geometry>
    </collision>
  </link>
  <joint
    name="F3J"
    type="revolute">
    <origin
      xyz="0.0071603 -0.042 -0.012402"
      rpy="0.42143 0.99089 0.49195" />
    <parent
      link="CH" />
    <child
      link="F3" />
    <axis
      xyz="0 0 1" />
    <limit
      lower="0"
      upper="1.0472"
      effort="10"
      velocity="0.125" />
    <safety_controller
      k_velocity="0" />
  </joint>
</robot>