<?xml version="1.0" encoding="utf-8"?>
<!-- This URDF was automatically created by SolidWorks to URDF Exporter! Originally created by Stephen Brawner (brawner@gmail.com) 
     Commit Version: 1.4.4-24-g24328f6  Build Version: 1.5.7084.36479
     For more information, please see http://wiki.ros.org/sw_urdf_exporter -->
<robot
  name="bot13">
  <link
    name="base_link">
    <inertial>
      <origin
        xyz="0.029232 0.047061 -5.6957E-05"
        rpy="0 0 0" />
      <mass
        value="10.067" />
      <inertia
        ixx="0.22006"
        ixy="-0.0014375"
        ixz="-6.9803E-05"
        iyy="0.35668"
        iyz="7.4306E-05"
        izz="0.19974" />
    </inertial>
    <visual>
      <origin
        xyz="0 0 0"
        rpy="0 0 0" />
      <geometry>
        <mesh
          filename="package://bot13/meshes/base_link.STL" />
      </geometry>
      <material
        name="">
        <color
          rgba="0.79216 0.81961 0.93333 1" />
      </material>
    </visual>
    <collision>
      <origin
        xyz="0 0 0"
        rpy="0 0 0" />
      <geometry>
        <mesh
          filename="package://bot13/meshes/base_link.STL" />
      </geometry>
    </collision>
  </link>
  <link
    name="FRW">
    <inertial>
      <origin
        xyz="0 -7.53920386007134E-05 -0.089381031363088"
        rpy="0 0 0" />
      <mass
        value="0.8334016991443" />
      <inertia
        ixx="0.00215743548655978"
        ixy="4.33680868994202E-19"
        ixz="1.75229940963233E-19"
        iyy="0.00216058181623486"
        iyz="-8.55705036383949E-07"
        izz="0.0039286091523943" />
    </inertial>
    <visual>
      <origin
        xyz="0 0 0"
        rpy="0 0 0" />
      <geometry>
        <mesh
          filename="package://bot13/meshes/FRW.STL" />
      </geometry>
      <material
        name="">
        <color
          rgba="0.792156862745098 0.819607843137255 0.933333333333333 1" />
      </material>
    </visual>
    <collision>
      <origin
        xyz="0 0 0"
        rpy="0 0 0" />
      <geometry>
        <mesh
          filename="package://bot13/meshes/FRW.STL" />
      </geometry>
    </collision>
  </link>
  <joint
    name="FRWJ"
    type="continuous">
    <origin
      xyz="0.125 -0.13 -0.025"
      rpy="1.5708 0.39309 -3.1416" />
    <parent
      link="base_link" />
    <child
      link="FRW" />
    <axis
      xyz="0 0 1" />
    <safety_controller
      k_velocity="0" />
  </joint>
  <link
    name="RRW">
    <inertial>
      <origin
        xyz="-2.77555756156289E-17 -7.53920386007342E-05 -0.089381031363088"
        rpy="0 0 0" />
      <mass
        value="0.8334016991443" />
      <inertia
        ixx="0.00215743548655978"
        ixy="6.50521303491303E-19"
        ixz="4.68515098950035E-20"
        iyy="0.00216058181623486"
        iyz="-8.55705036383984E-07"
        izz="0.0039286091523943" />
    </inertial>
    <visual>
      <origin
        xyz="0 0 0"
        rpy="0 0 0" />
      <geometry>
        <mesh
          filename="package://bot13/meshes/RRW.STL" />
      </geometry>
      <material
        name="">
        <color
          rgba="0.792156862745098 0.819607843137255 0.933333333333333 1" />
      </material>
    </visual>
    <collision>
      <origin
        xyz="0 0 0"
        rpy="0 0 0" />
      <geometry>
        <mesh
          filename="package://bot13/meshes/RRW.STL" />
      </geometry>
    </collision>
  </link>
  <joint
    name="RRWJ"
    type="continuous">
    <origin
      xyz="-0.125 -0.13 -0.025"
      rpy="1.5708 0.39309 -3.1416" />
    <parent
      link="base_link" />
    <child
      link="RRW" />
    <axis
      xyz="0 0 1" />
    <safety_controller
      k_velocity="0" />
  </joint>
  <link
    name="FLW">
    <inertial>
      <origin
        xyz="0 -7.5392E-05 -0.089381"
        rpy="0 0 0" />
      <mass
        value="0.8334" />
      <inertia
        ixx="0.0021574"
        ixy="-8.7964E-21"
        ixz="2.7837E-19"
        iyy="0.0021606"
        iyz="-8.5571E-07"
        izz="0.0039286" />
    </inertial>
    <visual>
      <origin
        xyz="0 0 0"
        rpy="0 0 0" />
      <geometry>
        <mesh
          filename="package://bot13/meshes/FLW.STL" />
      </geometry>
      <material
        name="">
        <color
          rgba="0.79216 0.81961 0.93333 1" />
      </material>
    </visual>
    <collision>
      <origin
        xyz="0 0 0"
        rpy="0 0 0" />
      <geometry>
        <mesh
          filename="package://bot13/meshes/FLW.STL" />
      </geometry>
    </collision>
  </link>
  <joint
    name="FLWJ"
    type="continuous">
    <origin
      xyz="0.125 0.13 -0.025"
      rpy="1.5708 0 0" />
    <parent
      link="base_link" />
    <child
      link="FLW" />
    <axis
      xyz="0 0 1" />
    <safety_controller
      k_velocity="0" />
  </joint>
  <link
    name="RLW">
    <inertial>
      <origin
        xyz="-1.38777878078145E-17 -7.53920386007238E-05 -0.0893810313630881"
        rpy="0 0 0" />
      <mass
        value="0.8334016991443" />
      <inertia
        ixx="0.00215743548655978"
        ixy="-8.79635490065067E-21"
        ixz="2.78368928810459E-19"
        iyy="0.00216058181623486"
        iyz="-8.5570503638385E-07"
        izz="0.0039286091523943" />
    </inertial>
    <visual>
      <origin
        xyz="0 0 0"
        rpy="0 0 0" />
      <geometry>
        <mesh
          filename="package://bot13/meshes/RLW.STL" />
      </geometry>
      <material
        name="">
        <color
          rgba="0.792156862745098 0.819607843137255 0.933333333333333 1" />
      </material>
    </visual>
    <collision>
      <origin
        xyz="0 0 0"
        rpy="0 0 0" />
      <geometry>
        <mesh
          filename="package://bot13/meshes/RLW.STL" />
      </geometry>
    </collision>
  </link>
  <joint
    name="RLWJ"
    type="continuous">
    <origin
      xyz="-0.125 0.13 -0.025"
      rpy="1.5708 0 0" />
    <parent
      link="base_link" />
    <child
      link="RLW" />
    <axis
      xyz="0 0 1" />
    <safety_controller
      k_velocity="0" />
  </joint>
  <link
    name="FC">
    <inertial>
      <origin
        xyz="0.015 -6.93889390390723E-18 -3.74580556821112E-17"
        rpy="0 0 0" />
      <mass
        value="0.0749999999999999" />
      <inertia
        ixx="3.125E-05"
        ixy="0"
        ixz="0"
        iyy="2.125E-05"
        iyz="-1.95156391047391E-21"
        izz="2.125E-05" />
    </inertial>
    <visual>
      <origin
        xyz="0 0 0"
        rpy="0 0 0" />
      <geometry>
        <mesh
          filename="package://bot13/meshes/FC.STL" />
      </geometry>
      <material
        name="">
        <color
          rgba="0.792156862745098 0.819607843137255 0.933333333333333 1" />
      </material>
    </visual>
    <collision>
      <origin
        xyz="0 0 0"
        rpy="0 0 0" />
      <geometry>
        <mesh
          filename="package://bot13/meshes/FC.STL" />
      </geometry>
    </collision>
  </link>
  <joint
    name="FCJ"
    type="fixed">
    <origin
      xyz="0.225 0 0.04"
      rpy="1.5708 0 0" />
    <parent
      link="base_link" />
    <child
      link="FC" />
    <axis
      xyz="0 0 0" />
    <safety_controller
      k_velocity="0" />
  </joint>
  <link
    name="RC">
    <inertial>
      <origin
        xyz="0.015 0 -6.93889390390723E-18"
        rpy="0 0 0" />
      <mass
        value="0.075" />
      <inertia
        ixx="3.125E-05"
        ixy="-1.62630325872826E-22"
        ixz="4.23516473627154E-22"
        iyy="2.125E-05"
        iyz="-1.30556011603463E-21"
        izz="2.125E-05" />
    </inertial>
    <visual>
      <origin
        xyz="0 0 0"
        rpy="0 0 0" />
      <geometry>
        <mesh
          filename="package://bot13/meshes/RC.STL" />
      </geometry>
      <material
        name="">
        <color
          rgba="0.792156862745098 0.819607843137255 0.933333333333333 1" />
      </material>
    </visual>
    <collision>
      <origin
        xyz="0 0 0"
        rpy="0 0 0" />
      <geometry>
        <mesh
          filename="package://bot13/meshes/RC.STL" />
      </geometry>
    </collision>
  </link>
  <joint
    name="RCJ"
    type="fixed">
    <origin
      xyz="0.05 -0.23 0.125"
      rpy="1.5708 0 1.5708" />
    <parent
      link="base_link" />
    <child
      link="RC" />
    <axis
      xyz="0 0 0" />
    <safety_controller
      k_velocity="0" />
  </joint>
  <link
    name="LC">
    <inertial>
      <origin
        xyz="0.015 0 6.93889390390723E-18"
        rpy="0 0 0" />
      <mass
        value="0.075" />
      <inertia
        ixx="3.125E-05"
        ixy="-1.62630325872825E-22"
        ixz="4.23516473627155E-22"
        iyy="2.125E-05"
        iyz="6.50521303491303E-22"
        izz="2.125E-05" />
    </inertial>
    <visual>
      <origin
        xyz="0 0 0"
        rpy="0 0 0" />
      <geometry>
        <mesh
          filename="package://bot13/meshes/LC.STL" />
      </geometry>
      <material
        name="">
        <color
          rgba="0.792156862745098 0.819607843137255 0.933333333333333 1" />
      </material>
    </visual>
    <collision>
      <origin
        xyz="0 0 0"
        rpy="0 0 0" />
      <geometry>
        <mesh
          filename="package://bot13/meshes/LC.STL" />
      </geometry>
    </collision>
  </link>
  <joint
    name="LCJ"
    type="fixed">
    <origin
      xyz="0.05 0.2 0.125"
      rpy="1.5708 0 1.5708" />
    <parent
      link="base_link" />
    <child
      link="LC" />
    <axis
      xyz="0 0 0" />
    <safety_controller
      k_velocity="0" />
  </joint>
  <link
    name="B">
    <inertial>
      <origin
        xyz="0.00625000000000001 0.099085 -2.21955375401734E-17"
        rpy="0 0 0" />
      <mass
        value="0.928921875000001" />
      <inertia
        ixx="0.0139258044771535"
        ixy="-1.03035018585451E-36"
        ixz="3.57062560219177E-20"
        iyy="0.0108978985595703"
        iyz="-5.01177010446494E-19"
        izz="0.00305209659141133" />
    </inertial>
    <visual>
      <origin
        xyz="0 0 0"
        rpy="0 0 0" />
      <geometry>
        <mesh
          filename="package://bot13/meshes/B.STL" />
      </geometry>
      <material
        name="">
        <color
          rgba="0.792156862745098 0.819607843137255 0.933333333333333 1" />
      </material>
    </visual>
    <collision>
      <origin
        xyz="0 0 0"
        rpy="0 0 0" />
      <geometry>
        <mesh
          filename="package://bot13/meshes/B.STL" />
      </geometry>
    </collision>
  </link>
  <joint
    name="BJ"
    type="prismatic">
    <origin
      xyz="-0.225 0 0.022817"
      rpy="1.5708 0 0" />
    <parent
      link="base_link" />
    <child
      link="B" />
    <axis
      xyz="0 1 0" />
    <limit
      lower="-0.15"
      upper="0"
      effort="100"
      velocity="0.2" />
    <safety_controller
      k_velocity="0" />
  </joint>
  <link
    name="EP1">
    <inertial>
      <origin
        xyz="0 0 0"
        rpy="0 0 0" />
      <mass
        value="0" />
      <inertia
        ixx="0"
        ixy="0"
        ixz="0"
        iyy="0"
        iyz="0"
        izz="0" />
    </inertial>
    <visual>
      <origin
        xyz="0 0 0"
        rpy="0 0 0" />
      <geometry>
        <mesh
          filename="package://bot13/meshes/EP1.STL" />
      </geometry>
      <material
        name="">
        <color
          rgba="1 1 1 1" />
      </material>
    </visual>
    <collision>
      <origin
        xyz="0 0 0"
        rpy="0 0 0" />
      <geometry>
        <mesh
          filename="package://bot13/meshes/EP1.STL" />
      </geometry>
    </collision>
  </link>
  <joint
    name="EP1J"
    type="prismatic">
    <origin
      xyz="0 0.005 0.33"
      rpy="1.5708 0 0" />
    <parent
      link="base_link" />
    <child
      link="EP1" />
    <axis
      xyz="1 0 0" />
    <limit
      lower="0"
      upper="0.35"
      effort="100"
      velocity="0.5" />
    <safety_controller
      k_velocity="0" />
  </joint>
  <link
    name="EP2">
    <inertial>
      <origin
        xyz="0 -0.14 -8.67361737988404E-19"
        rpy="0 0 0" />
      <mass
        value="0.12" />
      <inertia
        ixx="0.000904000000000001"
        ixy="-6.71011358594389E-37"
        ixz="-1.8901257873664E-22"
        iyy="8.00000000000001E-06"
        iyz="-2.11758236813575E-21"
        izz="0.000904000000000001" />
    </inertial>
    <visual>
      <origin
        xyz="0 0 0"
        rpy="0 0 0" />
      <geometry>
        <mesh
          filename="package://bot13/meshes/EP2.STL" />
      </geometry>
      <material
        name="">
        <color
          rgba="0.792156862745098 0.819607843137255 0.933333333333333 1" />
      </material>
    </visual>
    <collision>
      <origin
        xyz="0 0 0"
        rpy="0 0 0" />
      <geometry>
        <mesh
          filename="package://bot13/meshes/EP2.STL" />
      </geometry>
    </collision>
  </link>
  <joint
    name="EP2J"
    type="prismatic">
    <origin
      xyz="0.4575 0 0"
      rpy="0 0 0" />
    <parent
      link="EP1" />
    <child
      link="EP2" />
    <axis
      xyz="0 1 0" />
    <limit
      lower="-0.23"
      upper="0"
      effort="100"
      velocity="0.5" />
    <safety_controller
      k_velocity="0" />
  </joint>
  <link
    name="EP3">
    <inertial>
      <origin
        xyz="0 -3.46944695195361E-18 0.11"
        rpy="0 0 0" />
      <mass
        value="0.0880000000000001" />
      <inertia
        ixx="0.000357866666666667"
        ixy="7.59845022550256E-23"
        ixz="2.89771100632959E-22"
        iyy="0.000357866666666667"
        iyz="1.82145964977565E-21"
        izz="5.86666666666668E-06" />
    </inertial>
    <visual>
      <origin
        xyz="0 0 0"
        rpy="0 0 0" />
      <geometry>
        <mesh
          filename="package://bot13/meshes/EP3.STL" />
      </geometry>
      <material
        name="">
        <color
          rgba="0.792156862745098 0.819607843137255 0.933333333333333 1" />
      </material>
    </visual>
    <collision>
      <origin
        xyz="0 0 0"
        rpy="0 0 0" />
      <geometry>
        <mesh
          filename="package://bot13/meshes/EP3.STL" />
      </geometry>
    </collision>
  </link>
  <joint
    name="EP3J"
    type="fixed">
    <origin
      xyz="0 -0.3 -0.11"
      rpy="0 0 0" />
    <parent
      link="EP2" />
    <child
      link="EP3" />
    <axis
      xyz="0 0 0" />
    <safety_controller
      k_velocity="0" />
  </joint>
  <link
    name="FR">
    <inertial>
      <origin
        xyz="0.0750000000000001 0.0031858741301596 -0.0445144607159572"
        rpy="0 0 0" />
      <mass
        value="0.329828638625468" />
      <inertia
        ixx="0.000707899487326371"
        ixy="-2.85134458931942E-19"
        ixz="2.39051587715498E-19"
        iyy="0.000886130987887954"
        iyz="6.00853426152274E-06"
        izz="0.00143740871894828" />
    </inertial>
    <visual>
      <origin
        xyz="0 0 0"
        rpy="0 0 0" />
      <geometry>
        <mesh
          filename="package://bot13/meshes/FR.STL" />
      </geometry>
      <material
        name="">
        <color
          rgba="0.792156862745098 0.819607843137255 0.933333333333333 1" />
      </material>
    </visual>
    <collision>
      <origin
        xyz="0 0 0"
        rpy="0 0 0" />
      <geometry>
        <mesh
          filename="package://bot13/meshes/FR.STL" />
      </geometry>
    </collision>
  </link>
  <joint
    name="FRJ"
    type="prismatic">
    <origin
      xyz="0.075 -0.085 0.17"
      rpy="3.1416 0 3.1416" />
    <parent
      link="EP3" />
    <child
      link="FR" />
    <axis
      xyz="0 0 1" />
    <limit
      lower="-0.045"
      upper="0"
      effort="100"
      velocity="0.2" />
    <safety_controller
      k_velocity="0" />
  </joint>
  <link
    name="FL">
    <inertial>
      <origin
        xyz="0.0749999999999998 0.00318587413015963 0.00548553928404262"
        rpy="0 0 0" />
      <mass
        value="0.329828638625467" />
      <inertia
        ixx="0.000707899487326369"
        ixy="-6.40207226743562E-19"
        ixz="1.09417034419195E-18"
        iyy="0.00088613098788795"
        iyz="6.00853426152265E-06"
        izz="0.00143740871894827" />
    </inertial>
    <visual>
      <origin
        xyz="0 0 0"
        rpy="0 0 0" />
      <geometry>
        <mesh
          filename="package://bot13/meshes/FL.STL" />
      </geometry>
      <material
        name="">
        <color
          rgba="0.792156862745098 0.819607843137255 0.933333333333333 1" />
      </material>
    </visual>
    <collision>
      <origin
        xyz="0 0 0"
        rpy="0 0 0" />
      <geometry>
        <mesh
          filename="package://bot13/meshes/FL.STL" />
      </geometry>
    </collision>
  </link>
  <joint
    name="FLJ"
    type="prismatic">
    <origin
      xyz="-0.075 -0.085 0"
      rpy="0 0 0" />
    <parent
      link="EP3" />
    <child
      link="FL" />
    <axis
      xyz="0 0 1" />
    <limit
      lower="0"
      upper="0.045"
      effort="100"
      velocity="0.2" />
    <safety_controller
      k_velocity="0" />
  </joint>
</robot>